2025-03-11 18:20:14,518 [ERROR] Exception on /favicon.ico [GET]
Traceback (most recent call last):
  File "/usr/lib/python3/dist-packages/flask/app.py", line 1820, in full_dispatch_request
    rv = self.dispatch_request()
         ^^^^^^^^^^^^^^^^^^^^^^^
  File "/usr/lib/python3/dist-packages/flask/app.py", line 1785, in dispatch_request
    self.raise_routing_exception(req)
  File "/usr/lib/python3/dist-packages/flask/app.py", line 1767, in raise_routing_exception
    raise request.routing_exception  # type: ignore
    ^^^^^^^^^^^^^^^^^^^^^^^^^^^^^^^
  File "/usr/lib/python3/dist-packages/flask/ctx.py", line 351, in match_request
    result = self.url_adapter.match(return_rule=True)  # type: ignore
             ^^^^^^^^^^^^^^^^^^^^^^^^^^^^^^^^^^^^^^^^
  File "/usr/lib/python3/dist-packages/werkzeug/routing/map.py", line 624, in match
    raise NotFound() from None
werkzeug.exceptions.NotFound: 404 Not Found: The requested URL was not found on the server. If you entered the URL manually please check your spelling and try again.

During handling of the above exception, another exception occurred:

Traceback (most recent call last):
  File "/usr/lib/python3/dist-packages/flask/app.py", line 2525, in wsgi_app
    response = self.full_dispatch_request()
               ^^^^^^^^^^^^^^^^^^^^^^^^^^^^
  File "/usr/lib/python3/dist-packages/flask/app.py", line 1822, in full_dispatch_request
    rv = self.handle_user_exception(e)
         ^^^^^^^^^^^^^^^^^^^^^^^^^^^^^
  File "/usr/lib/python3/dist-packages/flask/app.py", line 1666, in handle_user_exception
    return self.handle_http_exception(e)
           ^^^^^^^^^^^^^^^^^^^^^^^^^^^^^
  File "/usr/lib/python3/dist-packages/flask/app.py", line 1606, in handle_http_exception
    return self.ensure_sync(handler)(e)
           ^^^^^^^^^^^^^^^^^^^^^^^^^^^^
  File "/home/Jobmanager/app/__init__.py", line 93, in page_not_found
    return app.render_template('404.html'), 404
           ^^^^^^^^^^^^^^^^^^^
AttributeError: 'Flask' object has no attribute 'render_template'
2025-03-11 18:20:44,901 [ERROR] Exception on /favicon.ico [GET]
Traceback (most recent call last):
  File "/usr/lib/python3/dist-packages/flask/app.py", line 1820, in full_dispatch_request
    rv = self.dispatch_request()
         ^^^^^^^^^^^^^^^^^^^^^^^
  File "/usr/lib/python3/dist-packages/flask/app.py", line 1785, in dispatch_request
    self.raise_routing_exception(req)
  File "/usr/lib/python3/dist-packages/flask/app.py", line 1767, in raise_routing_exception
    raise request.routing_exception  # type: ignore
    ^^^^^^^^^^^^^^^^^^^^^^^^^^^^^^^
  File "/usr/lib/python3/dist-packages/flask/ctx.py", line 351, in match_request
    result = self.url_adapter.match(return_rule=True)  # type: ignore
             ^^^^^^^^^^^^^^^^^^^^^^^^^^^^^^^^^^^^^^^^
  File "/usr/lib/python3/dist-packages/werkzeug/routing/map.py", line 624, in match
    raise NotFound() from None
werkzeug.exceptions.NotFound: 404 Not Found: The requested URL was not found on the server. If you entered the URL manually please check your spelling and try again.

During handling of the above exception, another exception occurred:

Traceback (most recent call last):
  File "/usr/lib/python3/dist-packages/flask/app.py", line 2525, in wsgi_app
    response = self.full_dispatch_request()
               ^^^^^^^^^^^^^^^^^^^^^^^^^^^^
  File "/usr/lib/python3/dist-packages/flask/app.py", line 1822, in full_dispatch_request
    rv = self.handle_user_exception(e)
         ^^^^^^^^^^^^^^^^^^^^^^^^^^^^^
  File "/usr/lib/python3/dist-packages/flask/app.py", line 1666, in handle_user_exception
    return self.handle_http_exception(e)
           ^^^^^^^^^^^^^^^^^^^^^^^^^^^^^
  File "/usr/lib/python3/dist-packages/flask/app.py", line 1606, in handle_http_exception
    return self.ensure_sync(handler)(e)
           ^^^^^^^^^^^^^^^^^^^^^^^^^^^^
  File "/home/Jobmanager/app/__init__.py", line 93, in page_not_found
    return app.render_template('404.html'), 404
           ^^^^^^^^^^^^^^^^^^^
AttributeError: 'Flask' object has no attribute 'render_template'
2025-03-11 18:22:28,334 [ERROR] Exception on /favicon.ico [GET]
Traceback (most recent call last):
  File "/usr/lib/python3/dist-packages/flask/app.py", line 1820, in full_dispatch_request
    rv = self.dispatch_request()
         ^^^^^^^^^^^^^^^^^^^^^^^
  File "/usr/lib/python3/dist-packages/flask/app.py", line 1785, in dispatch_request
    self.raise_routing_exception(req)
  File "/usr/lib/python3/dist-packages/flask/app.py", line 1767, in raise_routing_exception
    raise request.routing_exception  # type: ignore
    ^^^^^^^^^^^^^^^^^^^^^^^^^^^^^^^
  File "/usr/lib/python3/dist-packages/flask/ctx.py", line 351, in match_request
    result = self.url_adapter.match(return_rule=True)  # type: ignore
             ^^^^^^^^^^^^^^^^^^^^^^^^^^^^^^^^^^^^^^^^
  File "/usr/lib/python3/dist-packages/werkzeug/routing/map.py", line 624, in match
    raise NotFound() from None
werkzeug.exceptions.NotFound: 404 Not Found: The requested URL was not found on the server. If you entered the URL manually please check your spelling and try again.

During handling of the above exception, another exception occurred:

Traceback (most recent call last):
  File "/usr/lib/python3/dist-packages/flask/app.py", line 2525, in wsgi_app
    response = self.full_dispatch_request()
               ^^^^^^^^^^^^^^^^^^^^^^^^^^^^
  File "/usr/lib/python3/dist-packages/flask/app.py", line 1822, in full_dispatch_request
    rv = self.handle_user_exception(e)
         ^^^^^^^^^^^^^^^^^^^^^^^^^^^^^
  File "/usr/lib/python3/dist-packages/flask/app.py", line 1666, in handle_user_exception
    return self.handle_http_exception(e)
           ^^^^^^^^^^^^^^^^^^^^^^^^^^^^^
  File "/usr/lib/python3/dist-packages/flask/app.py", line 1606, in handle_http_exception
    return self.ensure_sync(handler)(e)
           ^^^^^^^^^^^^^^^^^^^^^^^^^^^^
  File "/home/Jobmanager/app/__init__.py", line 93, in page_not_found
    return app.render_template('404.html'), 404
           ^^^^^^^^^^^^^^^^^^^
AttributeError: 'Flask' object has no attribute 'render_template'
2025-03-11 18:22:33,744 [ERROR] Exception on /favicon.ico [GET]
Traceback (most recent call last):
  File "/usr/lib/python3/dist-packages/flask/app.py", line 1820, in full_dispatch_request
    rv = self.dispatch_request()
         ^^^^^^^^^^^^^^^^^^^^^^^
  File "/usr/lib/python3/dist-packages/flask/app.py", line 1785, in dispatch_request
    self.raise_routing_exception(req)
  File "/usr/lib/python3/dist-packages/flask/app.py", line 1767, in raise_routing_exception
    raise request.routing_exception  # type: ignore
    ^^^^^^^^^^^^^^^^^^^^^^^^^^^^^^^
  File "/usr/lib/python3/dist-packages/flask/ctx.py", line 351, in match_request
    result = self.url_adapter.match(return_rule=True)  # type: ignore
             ^^^^^^^^^^^^^^^^^^^^^^^^^^^^^^^^^^^^^^^^
  File "/usr/lib/python3/dist-packages/werkzeug/routing/map.py", line 624, in match
    raise NotFound() from None
werkzeug.exceptions.NotFound: 404 Not Found: The requested URL was not found on the server. If you entered the URL manually please check your spelling and try again.

During handling of the above exception, another exception occurred:

Traceback (most recent call last):
  File "/usr/lib/python3/dist-packages/flask/app.py", line 2525, in wsgi_app
    response = self.full_dispatch_request()
               ^^^^^^^^^^^^^^^^^^^^^^^^^^^^
  File "/usr/lib/python3/dist-packages/flask/app.py", line 1822, in full_dispatch_request
    rv = self.handle_user_exception(e)
         ^^^^^^^^^^^^^^^^^^^^^^^^^^^^^
  File "/usr/lib/python3/dist-packages/flask/app.py", line 1666, in handle_user_exception
    return self.handle_http_exception(e)
           ^^^^^^^^^^^^^^^^^^^^^^^^^^^^^
  File "/usr/lib/python3/dist-packages/flask/app.py", line 1606, in handle_http_exception
    return self.ensure_sync(handler)(e)
           ^^^^^^^^^^^^^^^^^^^^^^^^^^^^
  File "/home/Jobmanager/app/__init__.py", line 93, in page_not_found
    return app.render_template('404.html'), 404
           ^^^^^^^^^^^^^^^^^^^
AttributeError: 'Flask' object has no attribute 'render_template'
2025-03-11 19:10:09,666 [INFO] Starting timer for job 28
2025-03-11 19:10:09,666 [INFO] Stopping all active timers
2025-03-11 19:12:42,486 [ERROR] Exception on /favicon.ico [GET]
Traceback (most recent call last):
  File "/usr/lib/python3/dist-packages/flask/app.py", line 1820, in full_dispatch_request
    rv = self.dispatch_request()
         ^^^^^^^^^^^^^^^^^^^^^^^
  File "/usr/lib/python3/dist-packages/flask/app.py", line 1785, in dispatch_request
    self.raise_routing_exception(req)
  File "/usr/lib/python3/dist-packages/flask/app.py", line 1767, in raise_routing_exception
    raise request.routing_exception  # type: ignore
    ^^^^^^^^^^^^^^^^^^^^^^^^^^^^^^^
  File "/usr/lib/python3/dist-packages/flask/ctx.py", line 351, in match_request
    result = self.url_adapter.match(return_rule=True)  # type: ignore
             ^^^^^^^^^^^^^^^^^^^^^^^^^^^^^^^^^^^^^^^^
  File "/usr/lib/python3/dist-packages/werkzeug/routing/map.py", line 624, in match
    raise NotFound() from None
werkzeug.exceptions.NotFound: 404 Not Found: The requested URL was not found on the server. If you entered the URL manually please check your spelling and try again.

During handling of the above exception, another exception occurred:

Traceback (most recent call last):
  File "/usr/lib/python3/dist-packages/flask/app.py", line 2525, in wsgi_app
    response = self.full_dispatch_request()
               ^^^^^^^^^^^^^^^^^^^^^^^^^^^^
  File "/usr/lib/python3/dist-packages/flask/app.py", line 1822, in full_dispatch_request
    rv = self.handle_user_exception(e)
         ^^^^^^^^^^^^^^^^^^^^^^^^^^^^^
  File "/usr/lib/python3/dist-packages/flask/app.py", line 1666, in handle_user_exception
    return self.handle_http_exception(e)
           ^^^^^^^^^^^^^^^^^^^^^^^^^^^^^
  File "/usr/lib/python3/dist-packages/flask/app.py", line 1606, in handle_http_exception
    return self.ensure_sync(handler)(e)
           ^^^^^^^^^^^^^^^^^^^^^^^^^^^^
  File "/home/Jobmanager/app/__init__.py", line 93, in page_not_found
    return app.render_template('404.html'), 404
           ^^^^^^^^^^^^^^^^^^^
AttributeError: 'Flask' object has no attribute 'render_template'
2025-03-11 19:12:45,639 [ERROR] Exception on /favicon.ico [GET]
Traceback (most recent call last):
  File "/usr/lib/python3/dist-packages/flask/app.py", line 1820, in full_dispatch_request
    rv = self.dispatch_request()
         ^^^^^^^^^^^^^^^^^^^^^^^
  File "/usr/lib/python3/dist-packages/flask/app.py", line 1785, in dispatch_request
    self.raise_routing_exception(req)
  File "/usr/lib/python3/dist-packages/flask/app.py", line 1767, in raise_routing_exception
    raise request.routing_exception  # type: ignore
    ^^^^^^^^^^^^^^^^^^^^^^^^^^^^^^^
  File "/usr/lib/python3/dist-packages/flask/ctx.py", line 351, in match_request
    result = self.url_adapter.match(return_rule=True)  # type: ignore
             ^^^^^^^^^^^^^^^^^^^^^^^^^^^^^^^^^^^^^^^^
  File "/usr/lib/python3/dist-packages/werkzeug/routing/map.py", line 624, in match
    raise NotFound() from None
werkzeug.exceptions.NotFound: 404 Not Found: The requested URL was not found on the server. If you entered the URL manually please check your spelling and try again.

During handling of the above exception, another exception occurred:

Traceback (most recent call last):
  File "/usr/lib/python3/dist-packages/flask/app.py", line 2525, in wsgi_app
    response = self.full_dispatch_request()
               ^^^^^^^^^^^^^^^^^^^^^^^^^^^^
  File "/usr/lib/python3/dist-packages/flask/app.py", line 1822, in full_dispatch_request
    rv = self.handle_user_exception(e)
         ^^^^^^^^^^^^^^^^^^^^^^^^^^^^^
  File "/usr/lib/python3/dist-packages/flask/app.py", line 1666, in handle_user_exception
    return self.handle_http_exception(e)
           ^^^^^^^^^^^^^^^^^^^^^^^^^^^^^
  File "/usr/lib/python3/dist-packages/flask/app.py", line 1606, in handle_http_exception
    return self.ensure_sync(handler)(e)
           ^^^^^^^^^^^^^^^^^^^^^^^^^^^^
  File "/home/Jobmanager/app/__init__.py", line 93, in page_not_found
    return app.render_template('404.html'), 404
           ^^^^^^^^^^^^^^^^^^^
AttributeError: 'Flask' object has no attribute 'render_template'
2025-03-11 19:20:54,411 [ERROR] Exception on /favicon.ico [GET]
Traceback (most recent call last):
  File "/usr/lib/python3/dist-packages/flask/app.py", line 1820, in full_dispatch_request
    rv = self.dispatch_request()
         ^^^^^^^^^^^^^^^^^^^^^^^
  File "/usr/lib/python3/dist-packages/flask/app.py", line 1785, in dispatch_request
    self.raise_routing_exception(req)
  File "/usr/lib/python3/dist-packages/flask/app.py", line 1767, in raise_routing_exception
    raise request.routing_exception  # type: ignore
    ^^^^^^^^^^^^^^^^^^^^^^^^^^^^^^^
  File "/usr/lib/python3/dist-packages/flask/ctx.py", line 351, in match_request
    result = self.url_adapter.match(return_rule=True)  # type: ignore
             ^^^^^^^^^^^^^^^^^^^^^^^^^^^^^^^^^^^^^^^^
  File "/usr/lib/python3/dist-packages/werkzeug/routing/map.py", line 624, in match
    raise NotFound() from None
werkzeug.exceptions.NotFound: 404 Not Found: The requested URL was not found on the server. If you entered the URL manually please check your spelling and try again.

During handling of the above exception, another exception occurred:

Traceback (most recent call last):
  File "/usr/lib/python3/dist-packages/flask/app.py", line 2525, in wsgi_app
    response = self.full_dispatch_request()
               ^^^^^^^^^^^^^^^^^^^^^^^^^^^^
  File "/usr/lib/python3/dist-packages/flask/app.py", line 1822, in full_dispatch_request
    rv = self.handle_user_exception(e)
         ^^^^^^^^^^^^^^^^^^^^^^^^^^^^^
  File "/usr/lib/python3/dist-packages/flask/app.py", line 1666, in handle_user_exception
    return self.handle_http_exception(e)
           ^^^^^^^^^^^^^^^^^^^^^^^^^^^^^
  File "/usr/lib/python3/dist-packages/flask/app.py", line 1606, in handle_http_exception
    return self.ensure_sync(handler)(e)
           ^^^^^^^^^^^^^^^^^^^^^^^^^^^^
  File "/home/Jobmanager/app/__init__.py", line 93, in page_not_found
    return app.render_template('404.html'), 404
           ^^^^^^^^^^^^^^^^^^^
AttributeError: 'Flask' object has no attribute 'render_template'
2025-03-11 19:21:38,193 [ERROR] Exception on /favicon.ico [GET]
Traceback (most recent call last):
  File "/usr/lib/python3/dist-packages/flask/app.py", line 1820, in full_dispatch_request
    rv = self.dispatch_request()
         ^^^^^^^^^^^^^^^^^^^^^^^
  File "/usr/lib/python3/dist-packages/flask/app.py", line 1785, in dispatch_request
    self.raise_routing_exception(req)
  File "/usr/lib/python3/dist-packages/flask/app.py", line 1767, in raise_routing_exception
    raise request.routing_exception  # type: ignore
    ^^^^^^^^^^^^^^^^^^^^^^^^^^^^^^^
  File "/usr/lib/python3/dist-packages/flask/ctx.py", line 351, in match_request
    result = self.url_adapter.match(return_rule=True)  # type: ignore
             ^^^^^^^^^^^^^^^^^^^^^^^^^^^^^^^^^^^^^^^^
  File "/usr/lib/python3/dist-packages/werkzeug/routing/map.py", line 624, in match
    raise NotFound() from None
werkzeug.exceptions.NotFound: 404 Not Found: The requested URL was not found on the server. If you entered the URL manually please check your spelling and try again.

During handling of the above exception, another exception occurred:

Traceback (most recent call last):
  File "/usr/lib/python3/dist-packages/flask/app.py", line 2525, in wsgi_app
    response = self.full_dispatch_request()
               ^^^^^^^^^^^^^^^^^^^^^^^^^^^^
  File "/usr/lib/python3/dist-packages/flask/app.py", line 1822, in full_dispatch_request
    rv = self.handle_user_exception(e)
         ^^^^^^^^^^^^^^^^^^^^^^^^^^^^^
  File "/usr/lib/python3/dist-packages/flask/app.py", line 1666, in handle_user_exception
    return self.handle_http_exception(e)
           ^^^^^^^^^^^^^^^^^^^^^^^^^^^^^
  File "/usr/lib/python3/dist-packages/flask/app.py", line 1606, in handle_http_exception
    return self.ensure_sync(handler)(e)
           ^^^^^^^^^^^^^^^^^^^^^^^^^^^^
  File "/home/Jobmanager/app/__init__.py", line 93, in page_not_found
    return app.render_template('404.html'), 404
           ^^^^^^^^^^^^^^^^^^^
AttributeError: 'Flask' object has no attribute 'render_template'
2025-03-11 19:21:45,433 [ERROR] Exception on /favicon.ico [GET]
Traceback (most recent call last):
  File "/usr/lib/python3/dist-packages/flask/app.py", line 1820, in full_dispatch_request
    rv = self.dispatch_request()
         ^^^^^^^^^^^^^^^^^^^^^^^
  File "/usr/lib/python3/dist-packages/flask/app.py", line 1785, in dispatch_request
    self.raise_routing_exception(req)
  File "/usr/lib/python3/dist-packages/flask/app.py", line 1767, in raise_routing_exception
    raise request.routing_exception  # type: ignore
    ^^^^^^^^^^^^^^^^^^^^^^^^^^^^^^^
  File "/usr/lib/python3/dist-packages/flask/ctx.py", line 351, in match_request
    result = self.url_adapter.match(return_rule=True)  # type: ignore
             ^^^^^^^^^^^^^^^^^^^^^^^^^^^^^^^^^^^^^^^^
  File "/usr/lib/python3/dist-packages/werkzeug/routing/map.py", line 624, in match
    raise NotFound() from None
werkzeug.exceptions.NotFound: 404 Not Found: The requested URL was not found on the server. If you entered the URL manually please check your spelling and try again.

During handling of the above exception, another exception occurred:

Traceback (most recent call last):
  File "/usr/lib/python3/dist-packages/flask/app.py", line 2525, in wsgi_app
    response = self.full_dispatch_request()
               ^^^^^^^^^^^^^^^^^^^^^^^^^^^^
  File "/usr/lib/python3/dist-packages/flask/app.py", line 1822, in full_dispatch_request
    rv = self.handle_user_exception(e)
         ^^^^^^^^^^^^^^^^^^^^^^^^^^^^^
  File "/usr/lib/python3/dist-packages/flask/app.py", line 1666, in handle_user_exception
    return self.handle_http_exception(e)
           ^^^^^^^^^^^^^^^^^^^^^^^^^^^^^
  File "/usr/lib/python3/dist-packages/flask/app.py", line 1606, in handle_http_exception
    return self.ensure_sync(handler)(e)
           ^^^^^^^^^^^^^^^^^^^^^^^^^^^^
  File "/home/Jobmanager/app/__init__.py", line 93, in page_not_found
    return app.render_template('404.html'), 404
           ^^^^^^^^^^^^^^^^^^^
AttributeError: 'Flask' object has no attribute 'render_template'
2025-03-11 19:21:57,386 [ERROR] Exception on /favicon.ico [GET]
Traceback (most recent call last):
  File "/usr/lib/python3/dist-packages/flask/app.py", line 1820, in full_dispatch_request
    rv = self.dispatch_request()
         ^^^^^^^^^^^^^^^^^^^^^^^
  File "/usr/lib/python3/dist-packages/flask/app.py", line 1785, in dispatch_request
    self.raise_routing_exception(req)
  File "/usr/lib/python3/dist-packages/flask/app.py", line 1767, in raise_routing_exception
    raise request.routing_exception  # type: ignore
    ^^^^^^^^^^^^^^^^^^^^^^^^^^^^^^^
  File "/usr/lib/python3/dist-packages/flask/ctx.py", line 351, in match_request
    result = self.url_adapter.match(return_rule=True)  # type: ignore
             ^^^^^^^^^^^^^^^^^^^^^^^^^^^^^^^^^^^^^^^^
  File "/usr/lib/python3/dist-packages/werkzeug/routing/map.py", line 624, in match
    raise NotFound() from None
werkzeug.exceptions.NotFound: 404 Not Found: The requested URL was not found on the server. If you entered the URL manually please check your spelling and try again.

During handling of the above exception, another exception occurred:

Traceback (most recent call last):
  File "/usr/lib/python3/dist-packages/flask/app.py", line 2525, in wsgi_app
    response = self.full_dispatch_request()
               ^^^^^^^^^^^^^^^^^^^^^^^^^^^^
  File "/usr/lib/python3/dist-packages/flask/app.py", line 1822, in full_dispatch_request
    rv = self.handle_user_exception(e)
         ^^^^^^^^^^^^^^^^^^^^^^^^^^^^^
  File "/usr/lib/python3/dist-packages/flask/app.py", line 1666, in handle_user_exception
    return self.handle_http_exception(e)
           ^^^^^^^^^^^^^^^^^^^^^^^^^^^^^
  File "/usr/lib/python3/dist-packages/flask/app.py", line 1606, in handle_http_exception
    return self.ensure_sync(handler)(e)
           ^^^^^^^^^^^^^^^^^^^^^^^^^^^^
  File "/home/Jobmanager/app/__init__.py", line 93, in page_not_found
    return app.render_template('404.html'), 404
           ^^^^^^^^^^^^^^^^^^^
AttributeError: 'Flask' object has no attribute 'render_template'
2025-03-11 19:27:04,144 [ERROR] Exception on /favicon.ico [GET]
Traceback (most recent call last):
  File "/usr/lib/python3/dist-packages/flask/app.py", line 1820, in full_dispatch_request
    rv = self.dispatch_request()
         ^^^^^^^^^^^^^^^^^^^^^^^
  File "/usr/lib/python3/dist-packages/flask/app.py", line 1785, in dispatch_request
    self.raise_routing_exception(req)
  File "/usr/lib/python3/dist-packages/flask/app.py", line 1767, in raise_routing_exception
    raise request.routing_exception  # type: ignore
    ^^^^^^^^^^^^^^^^^^^^^^^^^^^^^^^
  File "/usr/lib/python3/dist-packages/flask/ctx.py", line 351, in match_request
    result = self.url_adapter.match(return_rule=True)  # type: ignore
             ^^^^^^^^^^^^^^^^^^^^^^^^^^^^^^^^^^^^^^^^
  File "/usr/lib/python3/dist-packages/werkzeug/routing/map.py", line 624, in match
    raise NotFound() from None
werkzeug.exceptions.NotFound: 404 Not Found: The requested URL was not found on the server. If you entered the URL manually please check your spelling and try again.

During handling of the above exception, another exception occurred:

Traceback (most recent call last):
  File "/usr/lib/python3/dist-packages/flask/app.py", line 2525, in wsgi_app
    response = self.full_dispatch_request()
               ^^^^^^^^^^^^^^^^^^^^^^^^^^^^
  File "/usr/lib/python3/dist-packages/flask/app.py", line 1822, in full_dispatch_request
    rv = self.handle_user_exception(e)
         ^^^^^^^^^^^^^^^^^^^^^^^^^^^^^
  File "/usr/lib/python3/dist-packages/flask/app.py", line 1666, in handle_user_exception
    return self.handle_http_exception(e)
           ^^^^^^^^^^^^^^^^^^^^^^^^^^^^^
  File "/usr/lib/python3/dist-packages/flask/app.py", line 1606, in handle_http_exception
    return self.ensure_sync(handler)(e)
           ^^^^^^^^^^^^^^^^^^^^^^^^^^^^
  File "/home/Jobmanager/app/__init__.py", line 93, in page_not_found
    return app.render_template('404.html'), 404
           ^^^^^^^^^^^^^^^^^^^
AttributeError: 'Flask' object has no attribute 'render_template'
2025-03-11 19:34:28,245 [ERROR] Exception on /apple-touch-icon-precomposed.png [GET]
Traceback (most recent call last):
  File "/usr/lib/python3/dist-packages/flask/app.py", line 1820, in full_dispatch_request
    rv = self.dispatch_request()
         ^^^^^^^^^^^^^^^^^^^^^^^
  File "/usr/lib/python3/dist-packages/flask/app.py", line 1785, in dispatch_request
    self.raise_routing_exception(req)
  File "/usr/lib/python3/dist-packages/flask/app.py", line 1767, in raise_routing_exception
    raise request.routing_exception  # type: ignore
    ^^^^^^^^^^^^^^^^^^^^^^^^^^^^^^^
  File "/usr/lib/python3/dist-packages/flask/ctx.py", line 351, in match_request
    result = self.url_adapter.match(return_rule=True)  # type: ignore
             ^^^^^^^^^^^^^^^^^^^^^^^^^^^^^^^^^^^^^^^^
  File "/usr/lib/python3/dist-packages/werkzeug/routing/map.py", line 624, in match
    raise NotFound() from None
werkzeug.exceptions.NotFound: 404 Not Found: The requested URL was not found on the server. If you entered the URL manually please check your spelling and try again.

During handling of the above exception, another exception occurred:

Traceback (most recent call last):
  File "/usr/lib/python3/dist-packages/flask/app.py", line 2525, in wsgi_app
    response = self.full_dispatch_request()
               ^^^^^^^^^^^^^^^^^^^^^^^^^^^^
  File "/usr/lib/python3/dist-packages/flask/app.py", line 1822, in full_dispatch_request
    rv = self.handle_user_exception(e)
         ^^^^^^^^^^^^^^^^^^^^^^^^^^^^^
  File "/usr/lib/python3/dist-packages/flask/app.py", line 1666, in handle_user_exception
    return self.handle_http_exception(e)
           ^^^^^^^^^^^^^^^^^^^^^^^^^^^^^
  File "/usr/lib/python3/dist-packages/flask/app.py", line 1606, in handle_http_exception
    return self.ensure_sync(handler)(e)
           ^^^^^^^^^^^^^^^^^^^^^^^^^^^^
  File "/home/Jobmanager/app/__init__.py", line 93, in page_not_found
    return app.render_template('404.html'), 404
           ^^^^^^^^^^^^^^^^^^^
AttributeError: 'Flask' object has no attribute 'render_template'
2025-03-11 19:34:28,260 [ERROR] Exception on /apple-touch-icon.png [GET]
Traceback (most recent call last):
  File "/usr/lib/python3/dist-packages/flask/app.py", line 1820, in full_dispatch_request
    rv = self.dispatch_request()
         ^^^^^^^^^^^^^^^^^^^^^^^
  File "/usr/lib/python3/dist-packages/flask/app.py", line 1785, in dispatch_request
    self.raise_routing_exception(req)
  File "/usr/lib/python3/dist-packages/flask/app.py", line 1767, in raise_routing_exception
    raise request.routing_exception  # type: ignore
    ^^^^^^^^^^^^^^^^^^^^^^^^^^^^^^^
  File "/usr/lib/python3/dist-packages/flask/ctx.py", line 351, in match_request
    result = self.url_adapter.match(return_rule=True)  # type: ignore
             ^^^^^^^^^^^^^^^^^^^^^^^^^^^^^^^^^^^^^^^^
  File "/usr/lib/python3/dist-packages/werkzeug/routing/map.py", line 624, in match
    raise NotFound() from None
werkzeug.exceptions.NotFound: 404 Not Found: The requested URL was not found on the server. If you entered the URL manually please check your spelling and try again.

During handling of the above exception, another exception occurred:

Traceback (most recent call last):
  File "/usr/lib/python3/dist-packages/flask/app.py", line 2525, in wsgi_app
    response = self.full_dispatch_request()
               ^^^^^^^^^^^^^^^^^^^^^^^^^^^^
  File "/usr/lib/python3/dist-packages/flask/app.py", line 1822, in full_dispatch_request
    rv = self.handle_user_exception(e)
         ^^^^^^^^^^^^^^^^^^^^^^^^^^^^^
  File "/usr/lib/python3/dist-packages/flask/app.py", line 1666, in handle_user_exception
    return self.handle_http_exception(e)
           ^^^^^^^^^^^^^^^^^^^^^^^^^^^^^
  File "/usr/lib/python3/dist-packages/flask/app.py", line 1606, in handle_http_exception
    return self.ensure_sync(handler)(e)
           ^^^^^^^^^^^^^^^^^^^^^^^^^^^^
  File "/home/Jobmanager/app/__init__.py", line 93, in page_not_found
    return app.render_template('404.html'), 404
           ^^^^^^^^^^^^^^^^^^^
AttributeError: 'Flask' object has no attribute 'render_template'
2025-03-11 19:34:28,260 [ERROR] Exception on /apple-touch-icon-precomposed.png [GET]
Traceback (most recent call last):
  File "/usr/lib/python3/dist-packages/flask/app.py", line 1820, in full_dispatch_request
    rv = self.dispatch_request()
         ^^^^^^^^^^^^^^^^^^^^^^^
  File "/usr/lib/python3/dist-packages/flask/app.py", line 1785, in dispatch_request
    self.raise_routing_exception(req)
  File "/usr/lib/python3/dist-packages/flask/app.py", line 1767, in raise_routing_exception
    raise request.routing_exception  # type: ignore
    ^^^^^^^^^^^^^^^^^^^^^^^^^^^^^^^
  File "/usr/lib/python3/dist-packages/flask/ctx.py", line 351, in match_request
    result = self.url_adapter.match(return_rule=True)  # type: ignore
             ^^^^^^^^^^^^^^^^^^^^^^^^^^^^^^^^^^^^^^^^
  File "/usr/lib/python3/dist-packages/werkzeug/routing/map.py", line 624, in match
    raise NotFound() from None
werkzeug.exceptions.NotFound: 404 Not Found: The requested URL was not found on the server. If you entered the URL manually please check your spelling and try again.

During handling of the above exception, another exception occurred:

Traceback (most recent call last):
  File "/usr/lib/python3/dist-packages/flask/app.py", line 2525, in wsgi_app
    response = self.full_dispatch_request()
               ^^^^^^^^^^^^^^^^^^^^^^^^^^^^
  File "/usr/lib/python3/dist-packages/flask/app.py", line 1822, in full_dispatch_request
    rv = self.handle_user_exception(e)
         ^^^^^^^^^^^^^^^^^^^^^^^^^^^^^
  File "/usr/lib/python3/dist-packages/flask/app.py", line 1666, in handle_user_exception
    return self.handle_http_exception(e)
           ^^^^^^^^^^^^^^^^^^^^^^^^^^^^^
  File "/usr/lib/python3/dist-packages/flask/app.py", line 1606, in handle_http_exception
    return self.ensure_sync(handler)(e)
           ^^^^^^^^^^^^^^^^^^^^^^^^^^^^
  File "/home/Jobmanager/app/__init__.py", line 93, in page_not_found
    return app.render_template('404.html'), 404
           ^^^^^^^^^^^^^^^^^^^
AttributeError: 'Flask' object has no attribute 'render_template'
2025-03-11 19:34:28,260 [ERROR] Exception on /favicon.ico [GET]
Traceback (most recent call last):
  File "/usr/lib/python3/dist-packages/flask/app.py", line 1820, in full_dispatch_request
    rv = self.dispatch_request()
         ^^^^^^^^^^^^^^^^^^^^^^^
  File "/usr/lib/python3/dist-packages/flask/app.py", line 1785, in dispatch_request
    self.raise_routing_exception(req)
  File "/usr/lib/python3/dist-packages/flask/app.py", line 1767, in raise_routing_exception
    raise request.routing_exception  # type: ignore
    ^^^^^^^^^^^^^^^^^^^^^^^^^^^^^^^
  File "/usr/lib/python3/dist-packages/flask/ctx.py", line 351, in match_request
    result = self.url_adapter.match(return_rule=True)  # type: ignore
             ^^^^^^^^^^^^^^^^^^^^^^^^^^^^^^^^^^^^^^^^
  File "/usr/lib/python3/dist-packages/werkzeug/routing/map.py", line 624, in match
    raise NotFound() from None
werkzeug.exceptions.NotFound: 404 Not Found: The requested URL was not found on the server. If you entered the URL manually please check your spelling and try again.

During handling of the above exception, another exception occurred:

Traceback (most recent call last):
  File "/usr/lib/python3/dist-packages/flask/app.py", line 2525, in wsgi_app
    response = self.full_dispatch_request()
               ^^^^^^^^^^^^^^^^^^^^^^^^^^^^
  File "/usr/lib/python3/dist-packages/flask/app.py", line 1822, in full_dispatch_request
    rv = self.handle_user_exception(e)
         ^^^^^^^^^^^^^^^^^^^^^^^^^^^^^
  File "/usr/lib/python3/dist-packages/flask/app.py", line 1666, in handle_user_exception
    return self.handle_http_exception(e)
           ^^^^^^^^^^^^^^^^^^^^^^^^^^^^^
  File "/usr/lib/python3/dist-packages/flask/app.py", line 1606, in handle_http_exception
    return self.ensure_sync(handler)(e)
           ^^^^^^^^^^^^^^^^^^^^^^^^^^^^
  File "/home/Jobmanager/app/__init__.py", line 93, in page_not_found
    return app.render_template('404.html'), 404
           ^^^^^^^^^^^^^^^^^^^
AttributeError: 'Flask' object has no attribute 'render_template'
2025-03-11 19:34:28,265 [ERROR] Exception on /favicon.ico [GET]
Traceback (most recent call last):
  File "/usr/lib/python3/dist-packages/flask/app.py", line 1820, in full_dispatch_request
    rv = self.dispatch_request()
         ^^^^^^^^^^^^^^^^^^^^^^^
  File "/usr/lib/python3/dist-packages/flask/app.py", line 1785, in dispatch_request
    self.raise_routing_exception(req)
  File "/usr/lib/python3/dist-packages/flask/app.py", line 1767, in raise_routing_exception
    raise request.routing_exception  # type: ignore
    ^^^^^^^^^^^^^^^^^^^^^^^^^^^^^^^
  File "/usr/lib/python3/dist-packages/flask/ctx.py", line 351, in match_request
    result = self.url_adapter.match(return_rule=True)  # type: ignore
             ^^^^^^^^^^^^^^^^^^^^^^^^^^^^^^^^^^^^^^^^
  File "/usr/lib/python3/dist-packages/werkzeug/routing/map.py", line 624, in match
    raise NotFound() from None
werkzeug.exceptions.NotFound: 404 Not Found: The requested URL was not found on the server. If you entered the URL manually please check your spelling and try again.

During handling of the above exception, another exception occurred:

Traceback (most recent call last):
  File "/usr/lib/python3/dist-packages/flask/app.py", line 2525, in wsgi_app
    response = self.full_dispatch_request()
               ^^^^^^^^^^^^^^^^^^^^^^^^^^^^
  File "/usr/lib/python3/dist-packages/flask/app.py", line 1822, in full_dispatch_request
    rv = self.handle_user_exception(e)
         ^^^^^^^^^^^^^^^^^^^^^^^^^^^^^
  File "/usr/lib/python3/dist-packages/flask/app.py", line 1666, in handle_user_exception
    return self.handle_http_exception(e)
           ^^^^^^^^^^^^^^^^^^^^^^^^^^^^^
  File "/usr/lib/python3/dist-packages/flask/app.py", line 1606, in handle_http_exception
    return self.ensure_sync(handler)(e)
           ^^^^^^^^^^^^^^^^^^^^^^^^^^^^
  File "/home/Jobmanager/app/__init__.py", line 93, in page_not_found
    return app.render_template('404.html'), 404
           ^^^^^^^^^^^^^^^^^^^
AttributeError: 'Flask' object has no attribute 'render_template'
2025-03-11 19:34:28,265 [ERROR] Exception on /apple-touch-icon.png [GET]
Traceback (most recent call last):
  File "/usr/lib/python3/dist-packages/flask/app.py", line 1820, in full_dispatch_request
    rv = self.dispatch_request()
         ^^^^^^^^^^^^^^^^^^^^^^^
  File "/usr/lib/python3/dist-packages/flask/app.py", line 1785, in dispatch_request
    self.raise_routing_exception(req)
  File "/usr/lib/python3/dist-packages/flask/app.py", line 1767, in raise_routing_exception
    raise request.routing_exception  # type: ignore
    ^^^^^^^^^^^^^^^^^^^^^^^^^^^^^^^
  File "/usr/lib/python3/dist-packages/flask/ctx.py", line 351, in match_request
    result = self.url_adapter.match(return_rule=True)  # type: ignore
             ^^^^^^^^^^^^^^^^^^^^^^^^^^^^^^^^^^^^^^^^
  File "/usr/lib/python3/dist-packages/werkzeug/routing/map.py", line 624, in match
    raise NotFound() from None
werkzeug.exceptions.NotFound: 404 Not Found: The requested URL was not found on the server. If you entered the URL manually please check your spelling and try again.

During handling of the above exception, another exception occurred:

Traceback (most recent call last):
  File "/usr/lib/python3/dist-packages/flask/app.py", line 2525, in wsgi_app
    response = self.full_dispatch_request()
               ^^^^^^^^^^^^^^^^^^^^^^^^^^^^
  File "/usr/lib/python3/dist-packages/flask/app.py", line 1822, in full_dispatch_request
    rv = self.handle_user_exception(e)
         ^^^^^^^^^^^^^^^^^^^^^^^^^^^^^
  File "/usr/lib/python3/dist-packages/flask/app.py", line 1666, in handle_user_exception
    return self.handle_http_exception(e)
           ^^^^^^^^^^^^^^^^^^^^^^^^^^^^^
  File "/usr/lib/python3/dist-packages/flask/app.py", line 1606, in handle_http_exception
    return self.ensure_sync(handler)(e)
           ^^^^^^^^^^^^^^^^^^^^^^^^^^^^
  File "/home/Jobmanager/app/__init__.py", line 93, in page_not_found
    return app.render_template('404.html'), 404
           ^^^^^^^^^^^^^^^^^^^
AttributeError: 'Flask' object has no attribute 'render_template'
2025-03-11 19:59:13,690 [INFO] Stopping timer for job 28
2025-03-11 19:59:21,020 [INFO] Weekly summary request - selected_week: None, show_all: False
2025-03-11 19:59:21,020 [INFO] No week selected, using current week: 2025-W11
2025-03-11 19:59:21,020 [INFO] Fetching available weeks
2025-03-11 19:59:21,021 [INFO] Found 35 distinct dates with time entries
2025-03-11 19:59:21,021 [INFO] Processed 6 unique weeks
2025-03-11 19:59:21,021 [INFO] Final view settings - selected_week: 2025-W11, show_all: False
2025-03-11 19:59:21,022 [INFO] Found 16 time entries for week 2025-W11
2025-03-11 20:00:08,839 [INFO] Root path: /home/Jobmanager
2025-03-11 20:00:08,839 [INFO] Current working directory: /home/Jobmanager
2025-03-11 20:00:08,839 [INFO] Instance path: /home/Jobmanager/instance
2025-03-11 20:00:08,839 [INFO] Creating full backup at: /home/Jobmanager/backups/jobmanager_backup_20250311_2000.zip
2025-03-11 20:00:08,839 [INFO] Adding file: /home/Jobmanager/run.py
2025-03-11 20:00:08,839 [INFO] Adding file: /home/Jobmanager/init_db.py
2025-03-11 20:00:08,840 [INFO] Adding to zip: app/db.py
2025-03-11 20:00:08,840 [INFO] Adding to zip: app/__init__.py
2025-03-11 20:00:08,840 [INFO] Adding to zip: app/schema.sql
2025-03-11 20:00:08,841 [INFO] Adding to zip: app/routes/image_routes.py
2025-03-11 20:00:08,841 [INFO] Adding to zip: app/routes/system_routes.py
2025-03-11 20:00:08,842 [INFO] Adding to zip: app/routes/__init__.py
2025-03-11 20:00:08,842 [INFO] Adding to zip: app/routes/customer_routes.py
2025-03-11 20:00:08,842 [INFO] Adding to zip: app/routes/job_routes.py
2025-03-11 20:00:08,843 [INFO] Adding to zip: app/routes/report_routes.py
2025-03-11 20:00:08,844 [INFO] Adding to zip: app/routes/timer_routes.py
2025-03-11 20:00:08,844 [INFO] Adding to zip: app/utils/date_helper.py
2025-03-11 20:00:08,844 [INFO] Adding to zip: app/utils/time_utils.py
2025-03-11 20:00:08,844 [INFO] Adding to zip: app/utils/job_utils.py
2025-03-11 20:00:08,845 [INFO] Adding to zip: app/utils/material_utils.py
2025-03-11 20:00:08,845 [INFO] Adding to zip: app/utils/timer_utils.py
2025-03-11 20:00:08,845 [INFO] Adding to zip: app/utils/__init__.py
2025-03-11 20:00:08,845 [INFO] Adding to zip: app/utils/invoice_utils.py
2025-03-11 20:00:08,846 [INFO] Adding to zip: app/utils/error_utils.py
2025-03-11 20:00:08,846 [INFO] Adding to zip: app/utils/profile_utils.py
2025-03-11 20:00:08,846 [INFO] Adding to zip: app/utils/image_utils.py
2025-03-11 20:00:08,846 [INFO] Adding to zip: app/templates/customer_form.html
2025-03-11 20:00:08,847 [INFO] Adding to zip: app/templates/quick_timer.html
2025-03-11 20:00:08,847 [INFO] Adding to zip: app/templates/system_settings.html
2025-03-11 20:00:08,847 [INFO] Adding to zip: app/templates/shared_images.html
2025-03-11 20:00:08,848 [INFO] Adding to zip: app/templates/weekly_summary.html
2025-03-11 20:00:08,848 [INFO] Adding to zip: app/templates/job_details.html
2025-03-11 20:00:08,849 [INFO] Adding to zip: app/templates/invoice.html
2025-03-11 20:00:08,850 [INFO] Adding to zip: app/templates/job_form.html
2025-03-11 20:00:08,850 [INFO] Adding to zip: app/templates/customer_list.html
2025-03-11 20:00:08,850 [INFO] Adding to zip: app/templates/500.html
2025-03-11 20:00:08,850 [INFO] Adding to zip: app/templates/base.html
2025-03-11 20:00:08,851 [INFO] Adding to zip: app/templates/profile_settings.html
2025-03-11 20:00:08,851 [INFO] Adding to zip: app/templates/job_list.html
2025-03-11 20:00:08,851 [INFO] Adding to zip: app/templates/404.html
2025-03-11 20:00:08,852 [INFO] Adding to zip: app/static/favicon.ico
2025-03-11 20:00:08,852 [INFO] Adding to zip: app/static/qr-quick_timer.svg
2025-03-11 20:00:08,852 [INFO] Adding to zip: app/static/css/styles.css.bak
2025-03-11 20:00:08,853 [INFO] Adding to zip: app/static/css/styles.css
2025-03-11 20:00:08,854 [INFO] Adding to zip: instance/user_profile.json
2025-03-11 20:00:08,854 [INFO] Full backup created at: /home/Jobmanager/backups/jobmanager_backup_20250311_2000.zip
2025-03-11 20:00:08,854 [INFO] Backup file exists: True
2025-03-11 20:00:13,105 [INFO] Root path: /home/Jobmanager
2025-03-11 20:00:13,106 [INFO] Current working directory: /home/Jobmanager
2025-03-11 20:00:13,106 [INFO] Instance path: /home/Jobmanager/instance
2025-03-11 20:00:13,106 [INFO] DB Path: /home/Jobmanager/instance/jobmanager.db
2025-03-11 20:00:13,106 [INFO] Backup Path: /home/Jobmanager/backups/db_backup_20250311_2000.db
2025-03-11 20:00:13,106 [INFO] Database backup created at: /home/Jobmanager/backups/db_backup_20250311_2000.db
2025-03-11 20:00:13,106 [INFO] Backup file exists: True
2025-03-11 20:00:20,801 [INFO] Weekly summary request - selected_week: None, show_all: False
2025-03-11 20:00:20,801 [INFO] No week selected, using current week: 2025-W11
2025-03-11 20:00:20,801 [INFO] Fetching available weeks
2025-03-11 20:00:20,801 [INFO] Found 35 distinct dates with time entries
2025-03-11 20:00:20,801 [INFO] Processed 6 unique weeks
2025-03-11 20:00:20,802 [INFO] Final view settings - selected_week: 2025-W11, show_all: False
2025-03-11 20:00:20,802 [INFO] Found 16 time entries for week 2025-W11
2025-03-11 20:37:25,346 [INFO] Weekly summary request - selected_week: None, show_all: False
2025-03-11 20:37:25,346 [INFO] No week selected, using current week: 2025-W11
2025-03-11 20:37:25,346 [INFO] Fetching available weeks
2025-03-11 20:37:25,347 [INFO] Found 35 distinct dates with time entries
2025-03-11 20:37:25,347 [INFO] Processed 6 unique weeks
2025-03-11 20:37:25,347 [INFO] Final view settings - selected_week: 2025-W11, show_all: False
2025-03-11 20:37:25,348 [INFO] Found 16 time entries for week 2025-W11
2025-03-12 07:50:08,925 [INFO] Weekly summary request - selected_week: None, show_all: False
2025-03-12 07:50:08,925 [INFO] No week selected, using current week: 2025-W11
2025-03-12 07:50:08,925 [INFO] Fetching available weeks
2025-03-12 07:50:08,925 [INFO] Found 35 distinct dates with time entries
2025-03-12 07:50:08,926 [INFO] Processed 6 unique weeks
2025-03-12 07:50:08,926 [INFO] Final view settings - selected_week: 2025-W11, show_all: False
2025-03-12 07:50:08,926 [INFO] Found 16 time entries for week 2025-W11
2025-03-12 07:55:11,245 [INFO] Weekly summary request - selected_week: None, show_all: False
2025-03-12 07:55:11,246 [INFO] No week selected, using current week: 2025-W11
2025-03-12 07:55:11,246 [INFO] Fetching available weeks
2025-03-12 07:55:11,246 [INFO] Found 35 distinct dates with time entries
2025-03-12 07:55:11,246 [INFO] Processed 6 unique weeks
2025-03-12 07:55:11,247 [INFO] Final view settings - selected_week: 2025-W11, show_all: False
2025-03-12 07:55:11,247 [INFO] Found 16 time entries for week 2025-W11
2025-03-12 07:55:58,031 [INFO] Weekly summary request - selected_week: 2025-W10, show_all: False
2025-03-12 07:55:58,031 [INFO] Fetching available weeks
2025-03-12 07:55:58,032 [INFO] Found 35 distinct dates with time entries
2025-03-12 07:55:58,032 [INFO] Processed 6 unique weeks
2025-03-12 07:55:58,032 [INFO] Week selected from dropdown: 2025-W10, setting show_all=False
2025-03-12 07:55:58,032 [INFO] Final view settings - selected_week: 2025-W10, show_all: False
2025-03-12 07:55:58,033 [INFO] Found 23 time entries for week 2025-W10
2025-03-12 07:56:54,049 [INFO] Weekly summary request - selected_week: 2025-W10, show_all: False
2025-03-12 07:56:54,049 [INFO] Fetching available weeks
2025-03-12 07:56:54,049 [INFO] Found 35 distinct dates with time entries
2025-03-12 07:56:54,050 [INFO] Processed 6 unique weeks
2025-03-12 07:56:54,050 [INFO] Week selected from dropdown: 2025-W10, setting show_all=False
2025-03-12 07:56:54,050 [INFO] Final view settings - selected_week: 2025-W10, show_all: False
2025-03-12 07:56:54,050 [INFO] Found 23 time entries for week 2025-W10
2025-03-12 08:04:43,252 [INFO] Starting timer for job 4
2025-03-12 08:04:43,252 [INFO] Stopping all active timers
2025-03-12 08:06:33,501 [INFO] User profile saved successfully
2025-03-12 08:06:46,703 [INFO] Weekly summary request - selected_week: None, show_all: False
2025-03-12 08:06:46,703 [INFO] No week selected, using current week: 2025-W11
2025-03-12 08:06:46,703 [INFO] Fetching available weeks
2025-03-12 08:06:46,704 [INFO] Found 36 distinct dates with time entries
2025-03-12 08:06:46,704 [INFO] Processed 6 unique weeks
2025-03-12 08:06:46,704 [INFO] Final view settings - selected_week: 2025-W11, show_all: False
2025-03-12 08:06:46,704 [INFO] Found 17 time entries for week 2025-W11
2025-03-12 08:07:09,166 [INFO] Stopping timer for job 4
2025-03-12 10:13:58,012 [INFO] Starting timer for job 28
2025-03-12 10:13:58,012 [INFO] Stopping all active timers
2025-03-12 11:15:12,193 [INFO] Starting timer for job 4
2025-03-12 11:15:12,193 [INFO] Stopping all active timers
2025-03-12 11:20:48,767 [ERROR] Exception on /static/css/file-upload.css [GET]
Traceback (most recent call last):
  File "/usr/lib/python3/dist-packages/flask/app.py", line 1820, in full_dispatch_request
    rv = self.dispatch_request()
         ^^^^^^^^^^^^^^^^^^^^^^^
  File "/usr/lib/python3/dist-packages/flask/app.py", line 1796, in dispatch_request
    return self.ensure_sync(self.view_functions[rule.endpoint])(**view_args)
           ^^^^^^^^^^^^^^^^^^^^^^^^^^^^^^^^^^^^^^^^^^^^^^^^^^^^^^^^^^^^^^^^^
  File "/usr/lib/python3/dist-packages/flask/app.py", line 713, in <lambda>
    view_func=lambda **kw: self_ref().send_static_file(**kw),  # type: ignore # noqa: B950
                           ^^^^^^^^^^^^^^^^^^^^^^^^^^^^^^^^^
  File "/usr/lib/python3/dist-packages/flask/scaffold.py", line 331, in send_static_file
    return send_from_directory(
           ^^^^^^^^^^^^^^^^^^^^
  File "/usr/lib/python3/dist-packages/flask/helpers.py", line 590, in send_from_directory
    return werkzeug.utils.send_from_directory(  # type: ignore[return-value]
           ^^^^^^^^^^^^^^^^^^^^^^^^^^^^^^^^^^^^^^^^^^^^^^^^^^^^^^^^^^^^^^^^^
  File "/usr/lib/python3/dist-packages/werkzeug/utils.py", line 586, in send_from_directory
    raise NotFound()
werkzeug.exceptions.NotFound: 404 Not Found: The requested URL was not found on the server. If you entered the URL manually please check your spelling and try again.

During handling of the above exception, another exception occurred:

Traceback (most recent call last):
  File "/usr/lib/python3/dist-packages/flask/app.py", line 2525, in wsgi_app
    response = self.full_dispatch_request()
               ^^^^^^^^^^^^^^^^^^^^^^^^^^^^
  File "/usr/lib/python3/dist-packages/flask/app.py", line 1822, in full_dispatch_request
    rv = self.handle_user_exception(e)
         ^^^^^^^^^^^^^^^^^^^^^^^^^^^^^
  File "/usr/lib/python3/dist-packages/flask/app.py", line 1666, in handle_user_exception
    return self.handle_http_exception(e)
           ^^^^^^^^^^^^^^^^^^^^^^^^^^^^^
  File "/usr/lib/python3/dist-packages/flask/app.py", line 1606, in handle_http_exception
    return self.ensure_sync(handler)(e)
           ^^^^^^^^^^^^^^^^^^^^^^^^^^^^
  File "/home/Jobmanager/app/__init__.py", line 93, in page_not_found
    return app.render_template('404.html'), 404
           ^^^^^^^^^^^^^^^^^^^
AttributeError: 'Flask' object has no attribute 'render_template'
2025-03-12 11:20:48,767 [ERROR] Exception on /static/js/file-upload.js [GET]
Traceback (most recent call last):
  File "/usr/lib/python3/dist-packages/flask/app.py", line 1820, in full_dispatch_request
    rv = self.dispatch_request()
         ^^^^^^^^^^^^^^^^^^^^^^^
  File "/usr/lib/python3/dist-packages/flask/app.py", line 1796, in dispatch_request
    return self.ensure_sync(self.view_functions[rule.endpoint])(**view_args)
           ^^^^^^^^^^^^^^^^^^^^^^^^^^^^^^^^^^^^^^^^^^^^^^^^^^^^^^^^^^^^^^^^^
  File "/usr/lib/python3/dist-packages/flask/app.py", line 713, in <lambda>
    view_func=lambda **kw: self_ref().send_static_file(**kw),  # type: ignore # noqa: B950
                           ^^^^^^^^^^^^^^^^^^^^^^^^^^^^^^^^^
  File "/usr/lib/python3/dist-packages/flask/scaffold.py", line 331, in send_static_file
    return send_from_directory(
           ^^^^^^^^^^^^^^^^^^^^
  File "/usr/lib/python3/dist-packages/flask/helpers.py", line 590, in send_from_directory
    return werkzeug.utils.send_from_directory(  # type: ignore[return-value]
           ^^^^^^^^^^^^^^^^^^^^^^^^^^^^^^^^^^^^^^^^^^^^^^^^^^^^^^^^^^^^^^^^^
  File "/usr/lib/python3/dist-packages/werkzeug/utils.py", line 586, in send_from_directory
    raise NotFound()
werkzeug.exceptions.NotFound: 404 Not Found: The requested URL was not found on the server. If you entered the URL manually please check your spelling and try again.

During handling of the above exception, another exception occurred:

Traceback (most recent call last):
  File "/usr/lib/python3/dist-packages/flask/app.py", line 2525, in wsgi_app
    response = self.full_dispatch_request()
               ^^^^^^^^^^^^^^^^^^^^^^^^^^^^
  File "/usr/lib/python3/dist-packages/flask/app.py", line 1822, in full_dispatch_request
    rv = self.handle_user_exception(e)
         ^^^^^^^^^^^^^^^^^^^^^^^^^^^^^
  File "/usr/lib/python3/dist-packages/flask/app.py", line 1666, in handle_user_exception
    return self.handle_http_exception(e)
           ^^^^^^^^^^^^^^^^^^^^^^^^^^^^^
  File "/usr/lib/python3/dist-packages/flask/app.py", line 1606, in handle_http_exception
    return self.ensure_sync(handler)(e)
           ^^^^^^^^^^^^^^^^^^^^^^^^^^^^
  File "/home/Jobmanager/app/__init__.py", line 93, in page_not_found
    return app.render_template('404.html'), 404
           ^^^^^^^^^^^^^^^^^^^
AttributeError: 'Flask' object has no attribute 'render_template'
2025-03-12 11:21:13,949 [ERROR] Exception on /static/css/file-upload.css [GET]
Traceback (most recent call last):
  File "/usr/lib/python3/dist-packages/flask/app.py", line 1820, in full_dispatch_request
    rv = self.dispatch_request()
         ^^^^^^^^^^^^^^^^^^^^^^^
  File "/usr/lib/python3/dist-packages/flask/app.py", line 1796, in dispatch_request
    return self.ensure_sync(self.view_functions[rule.endpoint])(**view_args)
           ^^^^^^^^^^^^^^^^^^^^^^^^^^^^^^^^^^^^^^^^^^^^^^^^^^^^^^^^^^^^^^^^^
  File "/usr/lib/python3/dist-packages/flask/app.py", line 713, in <lambda>
    view_func=lambda **kw: self_ref().send_static_file(**kw),  # type: ignore # noqa: B950
                           ^^^^^^^^^^^^^^^^^^^^^^^^^^^^^^^^^
  File "/usr/lib/python3/dist-packages/flask/scaffold.py", line 331, in send_static_file
    return send_from_directory(
           ^^^^^^^^^^^^^^^^^^^^
  File "/usr/lib/python3/dist-packages/flask/helpers.py", line 590, in send_from_directory
    return werkzeug.utils.send_from_directory(  # type: ignore[return-value]
           ^^^^^^^^^^^^^^^^^^^^^^^^^^^^^^^^^^^^^^^^^^^^^^^^^^^^^^^^^^^^^^^^^
  File "/usr/lib/python3/dist-packages/werkzeug/utils.py", line 586, in send_from_directory
    raise NotFound()
werkzeug.exceptions.NotFound: 404 Not Found: The requested URL was not found on the server. If you entered the URL manually please check your spelling and try again.

During handling of the above exception, another exception occurred:

Traceback (most recent call last):
  File "/usr/lib/python3/dist-packages/flask/app.py", line 2525, in wsgi_app
    response = self.full_dispatch_request()
               ^^^^^^^^^^^^^^^^^^^^^^^^^^^^
  File "/usr/lib/python3/dist-packages/flask/app.py", line 1822, in full_dispatch_request
    rv = self.handle_user_exception(e)
         ^^^^^^^^^^^^^^^^^^^^^^^^^^^^^
  File "/usr/lib/python3/dist-packages/flask/app.py", line 1666, in handle_user_exception
    return self.handle_http_exception(e)
           ^^^^^^^^^^^^^^^^^^^^^^^^^^^^^
  File "/usr/lib/python3/dist-packages/flask/app.py", line 1606, in handle_http_exception
    return self.ensure_sync(handler)(e)
           ^^^^^^^^^^^^^^^^^^^^^^^^^^^^
  File "/home/Jobmanager/app/__init__.py", line 93, in page_not_found
    return app.render_template('404.html'), 404
           ^^^^^^^^^^^^^^^^^^^
AttributeError: 'Flask' object has no attribute 'render_template'
2025-03-12 11:21:13,949 [ERROR] Exception on /static/js/file-upload.js [GET]
Traceback (most recent call last):
  File "/usr/lib/python3/dist-packages/flask/app.py", line 1820, in full_dispatch_request
    rv = self.dispatch_request()
         ^^^^^^^^^^^^^^^^^^^^^^^
  File "/usr/lib/python3/dist-packages/flask/app.py", line 1796, in dispatch_request
    return self.ensure_sync(self.view_functions[rule.endpoint])(**view_args)
           ^^^^^^^^^^^^^^^^^^^^^^^^^^^^^^^^^^^^^^^^^^^^^^^^^^^^^^^^^^^^^^^^^
  File "/usr/lib/python3/dist-packages/flask/app.py", line 713, in <lambda>
    view_func=lambda **kw: self_ref().send_static_file(**kw),  # type: ignore # noqa: B950
                           ^^^^^^^^^^^^^^^^^^^^^^^^^^^^^^^^^
  File "/usr/lib/python3/dist-packages/flask/scaffold.py", line 331, in send_static_file
    return send_from_directory(
           ^^^^^^^^^^^^^^^^^^^^
  File "/usr/lib/python3/dist-packages/flask/helpers.py", line 590, in send_from_directory
    return werkzeug.utils.send_from_directory(  # type: ignore[return-value]
           ^^^^^^^^^^^^^^^^^^^^^^^^^^^^^^^^^^^^^^^^^^^^^^^^^^^^^^^^^^^^^^^^^
  File "/usr/lib/python3/dist-packages/werkzeug/utils.py", line 586, in send_from_directory
    raise NotFound()
werkzeug.exceptions.NotFound: 404 Not Found: The requested URL was not found on the server. If you entered the URL manually please check your spelling and try again.

During handling of the above exception, another exception occurred:

Traceback (most recent call last):
  File "/usr/lib/python3/dist-packages/flask/app.py", line 2525, in wsgi_app
    response = self.full_dispatch_request()
               ^^^^^^^^^^^^^^^^^^^^^^^^^^^^
  File "/usr/lib/python3/dist-packages/flask/app.py", line 1822, in full_dispatch_request
    rv = self.handle_user_exception(e)
         ^^^^^^^^^^^^^^^^^^^^^^^^^^^^^
  File "/usr/lib/python3/dist-packages/flask/app.py", line 1666, in handle_user_exception
    return self.handle_http_exception(e)
           ^^^^^^^^^^^^^^^^^^^^^^^^^^^^^
  File "/usr/lib/python3/dist-packages/flask/app.py", line 1606, in handle_http_exception
    return self.ensure_sync(handler)(e)
           ^^^^^^^^^^^^^^^^^^^^^^^^^^^^
  File "/home/Jobmanager/app/__init__.py", line 93, in page_not_found
    return app.render_template('404.html'), 404
           ^^^^^^^^^^^^^^^^^^^
AttributeError: 'Flask' object has no attribute 'render_template'
2025-03-12 11:21:33,865 [ERROR] Exception on /static/js/file-upload.js [GET]
Traceback (most recent call last):
  File "/usr/lib/python3/dist-packages/flask/app.py", line 1820, in full_dispatch_request
    rv = self.dispatch_request()
         ^^^^^^^^^^^^^^^^^^^^^^^
  File "/usr/lib/python3/dist-packages/flask/app.py", line 1796, in dispatch_request
    return self.ensure_sync(self.view_functions[rule.endpoint])(**view_args)
           ^^^^^^^^^^^^^^^^^^^^^^^^^^^^^^^^^^^^^^^^^^^^^^^^^^^^^^^^^^^^^^^^^
  File "/usr/lib/python3/dist-packages/flask/app.py", line 713, in <lambda>
    view_func=lambda **kw: self_ref().send_static_file(**kw),  # type: ignore # noqa: B950
                           ^^^^^^^^^^^^^^^^^^^^^^^^^^^^^^^^^
  File "/usr/lib/python3/dist-packages/flask/scaffold.py", line 331, in send_static_file
    return send_from_directory(
           ^^^^^^^^^^^^^^^^^^^^
  File "/usr/lib/python3/dist-packages/flask/helpers.py", line 590, in send_from_directory
    return werkzeug.utils.send_from_directory(  # type: ignore[return-value]
           ^^^^^^^^^^^^^^^^^^^^^^^^^^^^^^^^^^^^^^^^^^^^^^^^^^^^^^^^^^^^^^^^^
  File "/usr/lib/python3/dist-packages/werkzeug/utils.py", line 586, in send_from_directory
    raise NotFound()
werkzeug.exceptions.NotFound: 404 Not Found: The requested URL was not found on the server. If you entered the URL manually please check your spelling and try again.

During handling of the above exception, another exception occurred:

Traceback (most recent call last):
  File "/usr/lib/python3/dist-packages/flask/app.py", line 2525, in wsgi_app
    response = self.full_dispatch_request()
               ^^^^^^^^^^^^^^^^^^^^^^^^^^^^
  File "/usr/lib/python3/dist-packages/flask/app.py", line 1822, in full_dispatch_request
    rv = self.handle_user_exception(e)
         ^^^^^^^^^^^^^^^^^^^^^^^^^^^^^
  File "/usr/lib/python3/dist-packages/flask/app.py", line 1666, in handle_user_exception
    return self.handle_http_exception(e)
           ^^^^^^^^^^^^^^^^^^^^^^^^^^^^^
  File "/usr/lib/python3/dist-packages/flask/app.py", line 1606, in handle_http_exception
    return self.ensure_sync(handler)(e)
           ^^^^^^^^^^^^^^^^^^^^^^^^^^^^
  File "/home/Jobmanager/app/__init__.py", line 93, in page_not_found
    return app.render_template('404.html'), 404
           ^^^^^^^^^^^^^^^^^^^
AttributeError: 'Flask' object has no attribute 'render_template'
2025-03-12 11:21:33,865 [ERROR] Exception on /static/css/file-upload.css [GET]
Traceback (most recent call last):
  File "/usr/lib/python3/dist-packages/flask/app.py", line 1820, in full_dispatch_request
    rv = self.dispatch_request()
         ^^^^^^^^^^^^^^^^^^^^^^^
  File "/usr/lib/python3/dist-packages/flask/app.py", line 1796, in dispatch_request
    return self.ensure_sync(self.view_functions[rule.endpoint])(**view_args)
           ^^^^^^^^^^^^^^^^^^^^^^^^^^^^^^^^^^^^^^^^^^^^^^^^^^^^^^^^^^^^^^^^^
  File "/usr/lib/python3/dist-packages/flask/app.py", line 713, in <lambda>
    view_func=lambda **kw: self_ref().send_static_file(**kw),  # type: ignore # noqa: B950
                           ^^^^^^^^^^^^^^^^^^^^^^^^^^^^^^^^^
  File "/usr/lib/python3/dist-packages/flask/scaffold.py", line 331, in send_static_file
    return send_from_directory(
           ^^^^^^^^^^^^^^^^^^^^
  File "/usr/lib/python3/dist-packages/flask/helpers.py", line 590, in send_from_directory
    return werkzeug.utils.send_from_directory(  # type: ignore[return-value]
           ^^^^^^^^^^^^^^^^^^^^^^^^^^^^^^^^^^^^^^^^^^^^^^^^^^^^^^^^^^^^^^^^^
  File "/usr/lib/python3/dist-packages/werkzeug/utils.py", line 586, in send_from_directory
    raise NotFound()
werkzeug.exceptions.NotFound: 404 Not Found: The requested URL was not found on the server. If you entered the URL manually please check your spelling and try again.

During handling of the above exception, another exception occurred:

Traceback (most recent call last):
  File "/usr/lib/python3/dist-packages/flask/app.py", line 2525, in wsgi_app
    response = self.full_dispatch_request()
               ^^^^^^^^^^^^^^^^^^^^^^^^^^^^
  File "/usr/lib/python3/dist-packages/flask/app.py", line 1822, in full_dispatch_request
    rv = self.handle_user_exception(e)
         ^^^^^^^^^^^^^^^^^^^^^^^^^^^^^
  File "/usr/lib/python3/dist-packages/flask/app.py", line 1666, in handle_user_exception
    return self.handle_http_exception(e)
           ^^^^^^^^^^^^^^^^^^^^^^^^^^^^^
  File "/usr/lib/python3/dist-packages/flask/app.py", line 1606, in handle_http_exception
    return self.ensure_sync(handler)(e)
           ^^^^^^^^^^^^^^^^^^^^^^^^^^^^
  File "/home/Jobmanager/app/__init__.py", line 93, in page_not_found
    return app.render_template('404.html'), 404
           ^^^^^^^^^^^^^^^^^^^
AttributeError: 'Flask' object has no attribute 'render_template'
2025-03-12 11:25:32,534 [ERROR] Exception on /static/js/file-upload.js [GET]
Traceback (most recent call last):
  File "/usr/lib/python3/dist-packages/flask/app.py", line 1820, in full_dispatch_request
    rv = self.dispatch_request()
         ^^^^^^^^^^^^^^^^^^^^^^^
  File "/usr/lib/python3/dist-packages/flask/app.py", line 1796, in dispatch_request
    return self.ensure_sync(self.view_functions[rule.endpoint])(**view_args)
           ^^^^^^^^^^^^^^^^^^^^^^^^^^^^^^^^^^^^^^^^^^^^^^^^^^^^^^^^^^^^^^^^^
  File "/usr/lib/python3/dist-packages/flask/app.py", line 713, in <lambda>
    view_func=lambda **kw: self_ref().send_static_file(**kw),  # type: ignore # noqa: B950
                           ^^^^^^^^^^^^^^^^^^^^^^^^^^^^^^^^^
  File "/usr/lib/python3/dist-packages/flask/scaffold.py", line 331, in send_static_file
    return send_from_directory(
           ^^^^^^^^^^^^^^^^^^^^
  File "/usr/lib/python3/dist-packages/flask/helpers.py", line 590, in send_from_directory
    return werkzeug.utils.send_from_directory(  # type: ignore[return-value]
           ^^^^^^^^^^^^^^^^^^^^^^^^^^^^^^^^^^^^^^^^^^^^^^^^^^^^^^^^^^^^^^^^^
  File "/usr/lib/python3/dist-packages/werkzeug/utils.py", line 586, in send_from_directory
    raise NotFound()
werkzeug.exceptions.NotFound: 404 Not Found: The requested URL was not found on the server. If you entered the URL manually please check your spelling and try again.

During handling of the above exception, another exception occurred:

Traceback (most recent call last):
  File "/usr/lib/python3/dist-packages/flask/app.py", line 2525, in wsgi_app
    response = self.full_dispatch_request()
               ^^^^^^^^^^^^^^^^^^^^^^^^^^^^
  File "/usr/lib/python3/dist-packages/flask/app.py", line 1822, in full_dispatch_request
    rv = self.handle_user_exception(e)
         ^^^^^^^^^^^^^^^^^^^^^^^^^^^^^
  File "/usr/lib/python3/dist-packages/flask/app.py", line 1666, in handle_user_exception
    return self.handle_http_exception(e)
           ^^^^^^^^^^^^^^^^^^^^^^^^^^^^^
  File "/usr/lib/python3/dist-packages/flask/app.py", line 1606, in handle_http_exception
    return self.ensure_sync(handler)(e)
           ^^^^^^^^^^^^^^^^^^^^^^^^^^^^
  File "/home/Jobmanager/app/__init__.py", line 93, in page_not_found
    return app.render_template('404.html'), 404
           ^^^^^^^^^^^^^^^^^^^
AttributeError: 'Flask' object has no attribute 'render_template'
2025-03-12 11:25:33,767 [ERROR] Exception on /static/js/file-upload.js [GET]
Traceback (most recent call last):
  File "/usr/lib/python3/dist-packages/flask/app.py", line 1820, in full_dispatch_request
    rv = self.dispatch_request()
         ^^^^^^^^^^^^^^^^^^^^^^^
  File "/usr/lib/python3/dist-packages/flask/app.py", line 1796, in dispatch_request
    return self.ensure_sync(self.view_functions[rule.endpoint])(**view_args)
           ^^^^^^^^^^^^^^^^^^^^^^^^^^^^^^^^^^^^^^^^^^^^^^^^^^^^^^^^^^^^^^^^^
  File "/usr/lib/python3/dist-packages/flask/app.py", line 713, in <lambda>
    view_func=lambda **kw: self_ref().send_static_file(**kw),  # type: ignore # noqa: B950
                           ^^^^^^^^^^^^^^^^^^^^^^^^^^^^^^^^^
  File "/usr/lib/python3/dist-packages/flask/scaffold.py", line 331, in send_static_file
    return send_from_directory(
           ^^^^^^^^^^^^^^^^^^^^
  File "/usr/lib/python3/dist-packages/flask/helpers.py", line 590, in send_from_directory
    return werkzeug.utils.send_from_directory(  # type: ignore[return-value]
           ^^^^^^^^^^^^^^^^^^^^^^^^^^^^^^^^^^^^^^^^^^^^^^^^^^^^^^^^^^^^^^^^^
  File "/usr/lib/python3/dist-packages/werkzeug/utils.py", line 586, in send_from_directory
    raise NotFound()
werkzeug.exceptions.NotFound: 404 Not Found: The requested URL was not found on the server. If you entered the URL manually please check your spelling and try again.

During handling of the above exception, another exception occurred:

Traceback (most recent call last):
  File "/usr/lib/python3/dist-packages/flask/app.py", line 2525, in wsgi_app
    response = self.full_dispatch_request()
               ^^^^^^^^^^^^^^^^^^^^^^^^^^^^
  File "/usr/lib/python3/dist-packages/flask/app.py", line 1822, in full_dispatch_request
    rv = self.handle_user_exception(e)
         ^^^^^^^^^^^^^^^^^^^^^^^^^^^^^
  File "/usr/lib/python3/dist-packages/flask/app.py", line 1666, in handle_user_exception
    return self.handle_http_exception(e)
           ^^^^^^^^^^^^^^^^^^^^^^^^^^^^^
  File "/usr/lib/python3/dist-packages/flask/app.py", line 1606, in handle_http_exception
    return self.ensure_sync(handler)(e)
           ^^^^^^^^^^^^^^^^^^^^^^^^^^^^
  File "/home/Jobmanager/app/__init__.py", line 93, in page_not_found
    return app.render_template('404.html'), 404
           ^^^^^^^^^^^^^^^^^^^
AttributeError: 'Flask' object has no attribute 'render_template'
2025-03-12 11:25:58,601 [ERROR] Exception on /static/js/file-upload.js [GET]
Traceback (most recent call last):
  File "/usr/lib/python3/dist-packages/flask/app.py", line 1820, in full_dispatch_request
    rv = self.dispatch_request()
         ^^^^^^^^^^^^^^^^^^^^^^^
  File "/usr/lib/python3/dist-packages/flask/app.py", line 1796, in dispatch_request
    return self.ensure_sync(self.view_functions[rule.endpoint])(**view_args)
           ^^^^^^^^^^^^^^^^^^^^^^^^^^^^^^^^^^^^^^^^^^^^^^^^^^^^^^^^^^^^^^^^^
  File "/usr/lib/python3/dist-packages/flask/app.py", line 713, in <lambda>
    view_func=lambda **kw: self_ref().send_static_file(**kw),  # type: ignore # noqa: B950
                           ^^^^^^^^^^^^^^^^^^^^^^^^^^^^^^^^^
  File "/usr/lib/python3/dist-packages/flask/scaffold.py", line 331, in send_static_file
    return send_from_directory(
           ^^^^^^^^^^^^^^^^^^^^
  File "/usr/lib/python3/dist-packages/flask/helpers.py", line 590, in send_from_directory
    return werkzeug.utils.send_from_directory(  # type: ignore[return-value]
           ^^^^^^^^^^^^^^^^^^^^^^^^^^^^^^^^^^^^^^^^^^^^^^^^^^^^^^^^^^^^^^^^^
  File "/usr/lib/python3/dist-packages/werkzeug/utils.py", line 586, in send_from_directory
    raise NotFound()
werkzeug.exceptions.NotFound: 404 Not Found: The requested URL was not found on the server. If you entered the URL manually please check your spelling and try again.

During handling of the above exception, another exception occurred:

Traceback (most recent call last):
  File "/usr/lib/python3/dist-packages/flask/app.py", line 2525, in wsgi_app
    response = self.full_dispatch_request()
               ^^^^^^^^^^^^^^^^^^^^^^^^^^^^
  File "/usr/lib/python3/dist-packages/flask/app.py", line 1822, in full_dispatch_request
    rv = self.handle_user_exception(e)
         ^^^^^^^^^^^^^^^^^^^^^^^^^^^^^
  File "/usr/lib/python3/dist-packages/flask/app.py", line 1666, in handle_user_exception
    return self.handle_http_exception(e)
           ^^^^^^^^^^^^^^^^^^^^^^^^^^^^^
  File "/usr/lib/python3/dist-packages/flask/app.py", line 1606, in handle_http_exception
    return self.ensure_sync(handler)(e)
           ^^^^^^^^^^^^^^^^^^^^^^^^^^^^
  File "/home/Jobmanager/app/__init__.py", line 93, in page_not_found
    return app.render_template('404.html'), 404
           ^^^^^^^^^^^^^^^^^^^
AttributeError: 'Flask' object has no attribute 'render_template'
2025-03-12 11:31:45,734 [ERROR] Exception on /static/js/file-upload.js [GET]
Traceback (most recent call last):
  File "/usr/lib/python3/dist-packages/flask/app.py", line 1820, in full_dispatch_request
    rv = self.dispatch_request()
         ^^^^^^^^^^^^^^^^^^^^^^^
  File "/usr/lib/python3/dist-packages/flask/app.py", line 1796, in dispatch_request
    return self.ensure_sync(self.view_functions[rule.endpoint])(**view_args)
           ^^^^^^^^^^^^^^^^^^^^^^^^^^^^^^^^^^^^^^^^^^^^^^^^^^^^^^^^^^^^^^^^^
  File "/usr/lib/python3/dist-packages/flask/app.py", line 713, in <lambda>
    view_func=lambda **kw: self_ref().send_static_file(**kw),  # type: ignore # noqa: B950
                           ^^^^^^^^^^^^^^^^^^^^^^^^^^^^^^^^^
  File "/usr/lib/python3/dist-packages/flask/scaffold.py", line 331, in send_static_file
    return send_from_directory(
           ^^^^^^^^^^^^^^^^^^^^
  File "/usr/lib/python3/dist-packages/flask/helpers.py", line 590, in send_from_directory
    return werkzeug.utils.send_from_directory(  # type: ignore[return-value]
           ^^^^^^^^^^^^^^^^^^^^^^^^^^^^^^^^^^^^^^^^^^^^^^^^^^^^^^^^^^^^^^^^^
  File "/usr/lib/python3/dist-packages/werkzeug/utils.py", line 586, in send_from_directory
    raise NotFound()
werkzeug.exceptions.NotFound: 404 Not Found: The requested URL was not found on the server. If you entered the URL manually please check your spelling and try again.

During handling of the above exception, another exception occurred:

Traceback (most recent call last):
  File "/usr/lib/python3/dist-packages/flask/app.py", line 2525, in wsgi_app
    response = self.full_dispatch_request()
               ^^^^^^^^^^^^^^^^^^^^^^^^^^^^
  File "/usr/lib/python3/dist-packages/flask/app.py", line 1822, in full_dispatch_request
    rv = self.handle_user_exception(e)
         ^^^^^^^^^^^^^^^^^^^^^^^^^^^^^
  File "/usr/lib/python3/dist-packages/flask/app.py", line 1666, in handle_user_exception
    return self.handle_http_exception(e)
           ^^^^^^^^^^^^^^^^^^^^^^^^^^^^^
  File "/usr/lib/python3/dist-packages/flask/app.py", line 1606, in handle_http_exception
    return self.ensure_sync(handler)(e)
           ^^^^^^^^^^^^^^^^^^^^^^^^^^^^
  File "/home/Jobmanager/app/__init__.py", line 93, in page_not_found
    return app.render_template('404.html'), 404
           ^^^^^^^^^^^^^^^^^^^
AttributeError: 'Flask' object has no attribute 'render_template'
2025-03-12 11:32:41,292 [ERROR] Exception on /static/js/file-upload.js [GET]
Traceback (most recent call last):
  File "/usr/lib/python3/dist-packages/flask/app.py", line 1820, in full_dispatch_request
    rv = self.dispatch_request()
         ^^^^^^^^^^^^^^^^^^^^^^^
  File "/usr/lib/python3/dist-packages/flask/app.py", line 1796, in dispatch_request
    return self.ensure_sync(self.view_functions[rule.endpoint])(**view_args)
           ^^^^^^^^^^^^^^^^^^^^^^^^^^^^^^^^^^^^^^^^^^^^^^^^^^^^^^^^^^^^^^^^^
  File "/usr/lib/python3/dist-packages/flask/app.py", line 713, in <lambda>
    view_func=lambda **kw: self_ref().send_static_file(**kw),  # type: ignore # noqa: B950
                           ^^^^^^^^^^^^^^^^^^^^^^^^^^^^^^^^^
  File "/usr/lib/python3/dist-packages/flask/scaffold.py", line 331, in send_static_file
    return send_from_directory(
           ^^^^^^^^^^^^^^^^^^^^
  File "/usr/lib/python3/dist-packages/flask/helpers.py", line 590, in send_from_directory
    return werkzeug.utils.send_from_directory(  # type: ignore[return-value]
           ^^^^^^^^^^^^^^^^^^^^^^^^^^^^^^^^^^^^^^^^^^^^^^^^^^^^^^^^^^^^^^^^^
  File "/usr/lib/python3/dist-packages/werkzeug/utils.py", line 586, in send_from_directory
    raise NotFound()
werkzeug.exceptions.NotFound: 404 Not Found: The requested URL was not found on the server. If you entered the URL manually please check your spelling and try again.

During handling of the above exception, another exception occurred:

Traceback (most recent call last):
  File "/usr/lib/python3/dist-packages/flask/app.py", line 2525, in wsgi_app
    response = self.full_dispatch_request()
               ^^^^^^^^^^^^^^^^^^^^^^^^^^^^
  File "/usr/lib/python3/dist-packages/flask/app.py", line 1822, in full_dispatch_request
    rv = self.handle_user_exception(e)
         ^^^^^^^^^^^^^^^^^^^^^^^^^^^^^
  File "/usr/lib/python3/dist-packages/flask/app.py", line 1666, in handle_user_exception
    return self.handle_http_exception(e)
           ^^^^^^^^^^^^^^^^^^^^^^^^^^^^^
  File "/usr/lib/python3/dist-packages/flask/app.py", line 1606, in handle_http_exception
    return self.ensure_sync(handler)(e)
           ^^^^^^^^^^^^^^^^^^^^^^^^^^^^
  File "/home/Jobmanager/app/__init__.py", line 93, in page_not_found
    return app.render_template('404.html'), 404
           ^^^^^^^^^^^^^^^^^^^
AttributeError: 'Flask' object has no attribute 'render_template'
2025-03-12 11:32:50,602 [INFO] Weekly summary request - selected_week: None, show_all: False
2025-03-12 11:32:50,602 [INFO] No week selected, using current week: 2025-W11
2025-03-12 11:32:50,602 [INFO] Fetching available weeks
2025-03-12 11:32:50,603 [INFO] Found 36 distinct dates with time entries
2025-03-12 11:32:50,603 [INFO] Processed 6 unique weeks
2025-03-12 11:32:50,603 [INFO] Final view settings - selected_week: 2025-W11, show_all: False
2025-03-12 11:32:50,603 [INFO] Found 19 time entries for week 2025-W11
2025-03-12 11:48:12,942 [INFO] Stopping timer for job 4
2025-03-12 12:57:25,818 [INFO] Weekly summary request - selected_week: None, show_all: False
2025-03-12 12:57:25,818 [INFO] No week selected, using current week: 2025-W11
2025-03-12 12:57:25,818 [INFO] Fetching available weeks
2025-03-12 12:57:25,818 [INFO] Found 36 distinct dates with time entries
2025-03-12 12:57:25,818 [INFO] Processed 6 unique weeks
2025-03-12 12:57:25,819 [INFO] Final view settings - selected_week: 2025-W11, show_all: False
2025-03-12 12:57:25,819 [INFO] Found 19 time entries for week 2025-W11
2025-03-12 12:57:29,225 [INFO] Weekly summary request - selected_week: 2025-W10, show_all: False
2025-03-12 12:57:29,225 [INFO] Fetching available weeks
2025-03-12 12:57:29,226 [INFO] Found 36 distinct dates with time entries
2025-03-12 12:57:29,226 [INFO] Processed 6 unique weeks
2025-03-12 12:57:29,226 [INFO] Week selected from dropdown: 2025-W10, setting show_all=False
2025-03-12 12:57:29,226 [INFO] Final view settings - selected_week: 2025-W10, show_all: False
2025-03-12 12:57:29,227 [INFO] Found 23 time entries for week 2025-W10
2025-03-12 12:57:46,915 [INFO] Weekly summary request - selected_week: 2025-W11, show_all: False
2025-03-12 12:57:46,916 [INFO] Fetching available weeks
2025-03-12 12:57:46,916 [INFO] Found 36 distinct dates with time entries
2025-03-12 12:57:46,916 [INFO] Processed 6 unique weeks
2025-03-12 12:57:46,916 [INFO] Week selected from dropdown: 2025-W11, setting show_all=False
2025-03-12 12:57:46,916 [INFO] Final view settings - selected_week: 2025-W11, show_all: False
2025-03-12 12:57:46,917 [INFO] Found 19 time entries for week 2025-W11
2025-03-12 12:58:09,897 [INFO] Weekly summary request - selected_week: 2025-W11, show_all: True
2025-03-12 12:58:09,897 [INFO] Fetching available weeks
2025-03-12 12:58:09,897 [INFO] Found 36 distinct dates with time entries
2025-03-12 12:58:09,898 [INFO] Processed 6 unique weeks
2025-03-12 12:58:09,898 [INFO] Final view settings - selected_week: 2025-W11, show_all: True
2025-03-12 12:58:09,899 [INFO] Generated summary for 6 weeks
2025-03-12 12:58:12,784 [INFO] Weekly summary request - selected_week: 2025-W10, show_all: False
2025-03-12 12:58:12,784 [INFO] Fetching available weeks
2025-03-12 12:58:12,784 [INFO] Found 36 distinct dates with time entries
2025-03-12 12:58:12,785 [INFO] Processed 6 unique weeks
2025-03-12 12:58:12,785 [INFO] Week selected from dropdown: 2025-W10, setting show_all=False
2025-03-12 12:58:12,785 [INFO] Final view settings - selected_week: 2025-W10, show_all: False
2025-03-12 12:58:12,785 [INFO] Found 23 time entries for week 2025-W10
2025-03-12 12:58:19,989 [INFO] Root path: /home/Jobmanager
2025-03-12 12:58:19,989 [INFO] Current working directory: /home/Jobmanager
2025-03-12 12:58:19,989 [INFO] Instance path: /home/Jobmanager/instance
2025-03-12 12:58:19,989 [INFO] Creating full backup at: /home/Jobmanager/backups/jobmanager_backup_20250312_1258.zip
2025-03-12 12:58:19,989 [INFO] Adding file: /home/Jobmanager/run.py
2025-03-12 12:58:19,990 [INFO] Adding file: /home/Jobmanager/init_db.py
2025-03-12 12:58:19,990 [INFO] Adding to zip: app/db.py
2025-03-12 12:58:19,990 [INFO] Adding to zip: app/__init__.py
2025-03-12 12:58:19,991 [INFO] Adding to zip: app/schema.sql
2025-03-12 12:58:19,991 [INFO] Adding to zip: app/routes/image_routes.py
2025-03-12 12:58:19,992 [INFO] Adding to zip: app/routes/system_routes.py
2025-03-12 12:58:19,992 [INFO] Adding to zip: app/routes/__init__.py
2025-03-12 12:58:19,992 [INFO] Adding to zip: app/routes/customer_routes.py
2025-03-12 12:58:19,993 [INFO] Adding to zip: app/routes/job_routes.py
2025-03-12 12:58:19,993 [INFO] Adding to zip: app/routes/report_routes.py
2025-03-12 12:58:19,994 [INFO] Adding to zip: app/routes/timer_routes.py
2025-03-12 12:58:19,994 [INFO] Adding to zip: app/utils/date_helper.py
2025-03-12 12:58:19,994 [INFO] Adding to zip: app/utils/time_utils.py
2025-03-12 12:58:19,995 [INFO] Adding to zip: app/utils/job_utils.py
2025-03-12 12:58:19,995 [INFO] Adding to zip: app/utils/material_utils.py
2025-03-12 12:58:19,995 [INFO] Adding to zip: app/utils/timer_utils.py
2025-03-12 12:58:19,996 [INFO] Adding to zip: app/utils/__init__.py
2025-03-12 12:58:19,996 [INFO] Adding to zip: app/utils/invoice_utils.py
2025-03-12 12:58:19,996 [INFO] Adding to zip: app/utils/error_utils.py
2025-03-12 12:58:19,996 [INFO] Adding to zip: app/utils/profile_utils.py
2025-03-12 12:58:19,996 [INFO] Adding to zip: app/utils/image_utils.py
2025-03-12 12:58:19,997 [INFO] Adding to zip: app/templates/customer_form.html
2025-03-12 12:58:19,997 [INFO] Adding to zip: app/templates/quick_timer.html
2025-03-12 12:58:19,997 [INFO] Adding to zip: app/templates/system_settings.html
2025-03-12 12:58:19,998 [INFO] Adding to zip: app/templates/shared_images.html
2025-03-12 12:58:19,998 [INFO] Adding to zip: app/templates/weekly_summary.html
2025-03-12 12:58:19,998 [INFO] Adding to zip: app/templates/job_details.html
2025-03-12 12:58:19,999 [INFO] Adding to zip: app/templates/invoice.html
2025-03-12 12:58:20,000 [INFO] Adding to zip: app/templates/job_form.html
2025-03-12 12:58:20,000 [INFO] Adding to zip: app/templates/customer_list.html
2025-03-12 12:58:20,001 [INFO] Adding to zip: app/templates/500.html
2025-03-12 12:58:20,001 [INFO] Adding to zip: app/templates/base.html
2025-03-12 12:58:20,001 [INFO] Adding to zip: app/templates/profile_settings.html
2025-03-12 12:58:20,002 [INFO] Adding to zip: app/templates/job_list.html
2025-03-12 12:58:20,002 [INFO] Adding to zip: app/templates/404.html
2025-03-12 12:58:20,002 [INFO] Adding to zip: app/static/favicon.ico
2025-03-12 12:58:20,003 [INFO] Adding to zip: app/static/qr-quick_timer.svg
2025-03-12 12:58:20,003 [INFO] Adding to zip: app/static/js/file_upload.js
2025-03-12 12:58:20,003 [INFO] Adding to zip: app/static/css/styles.css
2025-03-12 12:58:20,004 [INFO] Adding to zip: app/static/css/file-upload.css
2025-03-12 12:58:20,005 [INFO] Adding to zip: instance/user_profile.json
2025-03-12 12:58:20,005 [INFO] Full backup created at: /home/Jobmanager/backups/jobmanager_backup_20250312_1258.zip
2025-03-12 12:58:20,005 [INFO] Backup file exists: True
2025-03-12 13:01:40,682 [ERROR] Exception on /apple-touch-icon-precomposed.png [GET]
Traceback (most recent call last):
  File "/usr/lib/python3/dist-packages/flask/app.py", line 1820, in full_dispatch_request
    rv = self.dispatch_request()
         ^^^^^^^^^^^^^^^^^^^^^^^
  File "/usr/lib/python3/dist-packages/flask/app.py", line 1785, in dispatch_request
    self.raise_routing_exception(req)
  File "/usr/lib/python3/dist-packages/flask/app.py", line 1767, in raise_routing_exception
    raise request.routing_exception  # type: ignore
    ^^^^^^^^^^^^^^^^^^^^^^^^^^^^^^^
  File "/usr/lib/python3/dist-packages/flask/ctx.py", line 351, in match_request
    result = self.url_adapter.match(return_rule=True)  # type: ignore
             ^^^^^^^^^^^^^^^^^^^^^^^^^^^^^^^^^^^^^^^^
  File "/usr/lib/python3/dist-packages/werkzeug/routing/map.py", line 624, in match
    raise NotFound() from None
werkzeug.exceptions.NotFound: 404 Not Found: The requested URL was not found on the server. If you entered the URL manually please check your spelling and try again.

During handling of the above exception, another exception occurred:

Traceback (most recent call last):
  File "/usr/lib/python3/dist-packages/flask/app.py", line 2525, in wsgi_app
    response = self.full_dispatch_request()
               ^^^^^^^^^^^^^^^^^^^^^^^^^^^^
  File "/usr/lib/python3/dist-packages/flask/app.py", line 1822, in full_dispatch_request
    rv = self.handle_user_exception(e)
         ^^^^^^^^^^^^^^^^^^^^^^^^^^^^^
  File "/usr/lib/python3/dist-packages/flask/app.py", line 1666, in handle_user_exception
    return self.handle_http_exception(e)
           ^^^^^^^^^^^^^^^^^^^^^^^^^^^^^
  File "/usr/lib/python3/dist-packages/flask/app.py", line 1606, in handle_http_exception
    return self.ensure_sync(handler)(e)
           ^^^^^^^^^^^^^^^^^^^^^^^^^^^^
  File "/home/Jobmanager/app/__init__.py", line 93, in page_not_found
    return app.render_template('404.html'), 404
           ^^^^^^^^^^^^^^^^^^^
AttributeError: 'Flask' object has no attribute 'render_template'
2025-03-12 13:01:40,691 [ERROR] Exception on /favicon.ico [GET]
Traceback (most recent call last):
  File "/usr/lib/python3/dist-packages/flask/app.py", line 1820, in full_dispatch_request
    rv = self.dispatch_request()
         ^^^^^^^^^^^^^^^^^^^^^^^
  File "/usr/lib/python3/dist-packages/flask/app.py", line 1785, in dispatch_request
    self.raise_routing_exception(req)
  File "/usr/lib/python3/dist-packages/flask/app.py", line 1767, in raise_routing_exception
    raise request.routing_exception  # type: ignore
    ^^^^^^^^^^^^^^^^^^^^^^^^^^^^^^^
  File "/usr/lib/python3/dist-packages/flask/ctx.py", line 351, in match_request
    result = self.url_adapter.match(return_rule=True)  # type: ignore
             ^^^^^^^^^^^^^^^^^^^^^^^^^^^^^^^^^^^^^^^^
  File "/usr/lib/python3/dist-packages/werkzeug/routing/map.py", line 624, in match
    raise NotFound() from None
werkzeug.exceptions.NotFound: 404 Not Found: The requested URL was not found on the server. If you entered the URL manually please check your spelling and try again.

During handling of the above exception, another exception occurred:

Traceback (most recent call last):
  File "/usr/lib/python3/dist-packages/flask/app.py", line 2525, in wsgi_app
    response = self.full_dispatch_request()
               ^^^^^^^^^^^^^^^^^^^^^^^^^^^^
  File "/usr/lib/python3/dist-packages/flask/app.py", line 1822, in full_dispatch_request
    rv = self.handle_user_exception(e)
         ^^^^^^^^^^^^^^^^^^^^^^^^^^^^^
  File "/usr/lib/python3/dist-packages/flask/app.py", line 1666, in handle_user_exception
    return self.handle_http_exception(e)
           ^^^^^^^^^^^^^^^^^^^^^^^^^^^^^
  File "/usr/lib/python3/dist-packages/flask/app.py", line 1606, in handle_http_exception
    return self.ensure_sync(handler)(e)
           ^^^^^^^^^^^^^^^^^^^^^^^^^^^^
  File "/home/Jobmanager/app/__init__.py", line 93, in page_not_found
    return app.render_template('404.html'), 404
           ^^^^^^^^^^^^^^^^^^^
AttributeError: 'Flask' object has no attribute 'render_template'
2025-03-12 13:01:40,691 [ERROR] Exception on /apple-touch-icon.png [GET]
Traceback (most recent call last):
  File "/usr/lib/python3/dist-packages/flask/app.py", line 1820, in full_dispatch_request
    rv = self.dispatch_request()
         ^^^^^^^^^^^^^^^^^^^^^^^
  File "/usr/lib/python3/dist-packages/flask/app.py", line 1785, in dispatch_request
    self.raise_routing_exception(req)
  File "/usr/lib/python3/dist-packages/flask/app.py", line 1767, in raise_routing_exception
    raise request.routing_exception  # type: ignore
    ^^^^^^^^^^^^^^^^^^^^^^^^^^^^^^^
  File "/usr/lib/python3/dist-packages/flask/ctx.py", line 351, in match_request
    result = self.url_adapter.match(return_rule=True)  # type: ignore
             ^^^^^^^^^^^^^^^^^^^^^^^^^^^^^^^^^^^^^^^^
  File "/usr/lib/python3/dist-packages/werkzeug/routing/map.py", line 624, in match
    raise NotFound() from None
werkzeug.exceptions.NotFound: 404 Not Found: The requested URL was not found on the server. If you entered the URL manually please check your spelling and try again.

During handling of the above exception, another exception occurred:

Traceback (most recent call last):
  File "/usr/lib/python3/dist-packages/flask/app.py", line 2525, in wsgi_app
    response = self.full_dispatch_request()
               ^^^^^^^^^^^^^^^^^^^^^^^^^^^^
  File "/usr/lib/python3/dist-packages/flask/app.py", line 1822, in full_dispatch_request
    rv = self.handle_user_exception(e)
         ^^^^^^^^^^^^^^^^^^^^^^^^^^^^^
  File "/usr/lib/python3/dist-packages/flask/app.py", line 1666, in handle_user_exception
    return self.handle_http_exception(e)
           ^^^^^^^^^^^^^^^^^^^^^^^^^^^^^
  File "/usr/lib/python3/dist-packages/flask/app.py", line 1606, in handle_http_exception
    return self.ensure_sync(handler)(e)
           ^^^^^^^^^^^^^^^^^^^^^^^^^^^^
  File "/home/Jobmanager/app/__init__.py", line 93, in page_not_found
    return app.render_template('404.html'), 404
           ^^^^^^^^^^^^^^^^^^^
AttributeError: 'Flask' object has no attribute 'render_template'
2025-03-12 13:01:40,709 [ERROR] Exception on /apple-touch-icon-precomposed.png [GET]
Traceback (most recent call last):
  File "/usr/lib/python3/dist-packages/flask/app.py", line 1820, in full_dispatch_request
    rv = self.dispatch_request()
         ^^^^^^^^^^^^^^^^^^^^^^^
  File "/usr/lib/python3/dist-packages/flask/app.py", line 1785, in dispatch_request
    self.raise_routing_exception(req)
  File "/usr/lib/python3/dist-packages/flask/app.py", line 1767, in raise_routing_exception
    raise request.routing_exception  # type: ignore
    ^^^^^^^^^^^^^^^^^^^^^^^^^^^^^^^
  File "/usr/lib/python3/dist-packages/flask/ctx.py", line 351, in match_request
    result = self.url_adapter.match(return_rule=True)  # type: ignore
             ^^^^^^^^^^^^^^^^^^^^^^^^^^^^^^^^^^^^^^^^
  File "/usr/lib/python3/dist-packages/werkzeug/routing/map.py", line 624, in match
    raise NotFound() from None
werkzeug.exceptions.NotFound: 404 Not Found: The requested URL was not found on the server. If you entered the URL manually please check your spelling and try again.

During handling of the above exception, another exception occurred:

Traceback (most recent call last):
  File "/usr/lib/python3/dist-packages/flask/app.py", line 2525, in wsgi_app
    response = self.full_dispatch_request()
               ^^^^^^^^^^^^^^^^^^^^^^^^^^^^
  File "/usr/lib/python3/dist-packages/flask/app.py", line 1822, in full_dispatch_request
    rv = self.handle_user_exception(e)
         ^^^^^^^^^^^^^^^^^^^^^^^^^^^^^
  File "/usr/lib/python3/dist-packages/flask/app.py", line 1666, in handle_user_exception
    return self.handle_http_exception(e)
           ^^^^^^^^^^^^^^^^^^^^^^^^^^^^^
  File "/usr/lib/python3/dist-packages/flask/app.py", line 1606, in handle_http_exception
    return self.ensure_sync(handler)(e)
           ^^^^^^^^^^^^^^^^^^^^^^^^^^^^
  File "/home/Jobmanager/app/__init__.py", line 93, in page_not_found
    return app.render_template('404.html'), 404
           ^^^^^^^^^^^^^^^^^^^
AttributeError: 'Flask' object has no attribute 'render_template'
2025-03-12 13:01:40,711 [ERROR] Exception on /apple-touch-icon.png [GET]
Traceback (most recent call last):
  File "/usr/lib/python3/dist-packages/flask/app.py", line 1820, in full_dispatch_request
    rv = self.dispatch_request()
         ^^^^^^^^^^^^^^^^^^^^^^^
  File "/usr/lib/python3/dist-packages/flask/app.py", line 1785, in dispatch_request
    self.raise_routing_exception(req)
  File "/usr/lib/python3/dist-packages/flask/app.py", line 1767, in raise_routing_exception
    raise request.routing_exception  # type: ignore
    ^^^^^^^^^^^^^^^^^^^^^^^^^^^^^^^
  File "/usr/lib/python3/dist-packages/flask/ctx.py", line 351, in match_request
    result = self.url_adapter.match(return_rule=True)  # type: ignore
             ^^^^^^^^^^^^^^^^^^^^^^^^^^^^^^^^^^^^^^^^
  File "/usr/lib/python3/dist-packages/werkzeug/routing/map.py", line 624, in match
    raise NotFound() from None
werkzeug.exceptions.NotFound: 404 Not Found: The requested URL was not found on the server. If you entered the URL manually please check your spelling and try again.

During handling of the above exception, another exception occurred:

Traceback (most recent call last):
  File "/usr/lib/python3/dist-packages/flask/app.py", line 2525, in wsgi_app
    response = self.full_dispatch_request()
               ^^^^^^^^^^^^^^^^^^^^^^^^^^^^
  File "/usr/lib/python3/dist-packages/flask/app.py", line 1822, in full_dispatch_request
    rv = self.handle_user_exception(e)
         ^^^^^^^^^^^^^^^^^^^^^^^^^^^^^
  File "/usr/lib/python3/dist-packages/flask/app.py", line 1666, in handle_user_exception
    return self.handle_http_exception(e)
           ^^^^^^^^^^^^^^^^^^^^^^^^^^^^^
  File "/usr/lib/python3/dist-packages/flask/app.py", line 1606, in handle_http_exception
    return self.ensure_sync(handler)(e)
           ^^^^^^^^^^^^^^^^^^^^^^^^^^^^
  File "/home/Jobmanager/app/__init__.py", line 93, in page_not_found
    return app.render_template('404.html'), 404
           ^^^^^^^^^^^^^^^^^^^
AttributeError: 'Flask' object has no attribute 'render_template'
2025-03-12 13:01:40,712 [ERROR] Exception on /favicon.ico [GET]
Traceback (most recent call last):
  File "/usr/lib/python3/dist-packages/flask/app.py", line 1820, in full_dispatch_request
    rv = self.dispatch_request()
         ^^^^^^^^^^^^^^^^^^^^^^^
  File "/usr/lib/python3/dist-packages/flask/app.py", line 1785, in dispatch_request
    self.raise_routing_exception(req)
  File "/usr/lib/python3/dist-packages/flask/app.py", line 1767, in raise_routing_exception
    raise request.routing_exception  # type: ignore
    ^^^^^^^^^^^^^^^^^^^^^^^^^^^^^^^
  File "/usr/lib/python3/dist-packages/flask/ctx.py", line 351, in match_request
    result = self.url_adapter.match(return_rule=True)  # type: ignore
             ^^^^^^^^^^^^^^^^^^^^^^^^^^^^^^^^^^^^^^^^
  File "/usr/lib/python3/dist-packages/werkzeug/routing/map.py", line 624, in match
    raise NotFound() from None
werkzeug.exceptions.NotFound: 404 Not Found: The requested URL was not found on the server. If you entered the URL manually please check your spelling and try again.

During handling of the above exception, another exception occurred:

Traceback (most recent call last):
  File "/usr/lib/python3/dist-packages/flask/app.py", line 2525, in wsgi_app
    response = self.full_dispatch_request()
               ^^^^^^^^^^^^^^^^^^^^^^^^^^^^
  File "/usr/lib/python3/dist-packages/flask/app.py", line 1822, in full_dispatch_request
    rv = self.handle_user_exception(e)
         ^^^^^^^^^^^^^^^^^^^^^^^^^^^^^
  File "/usr/lib/python3/dist-packages/flask/app.py", line 1666, in handle_user_exception
    return self.handle_http_exception(e)
           ^^^^^^^^^^^^^^^^^^^^^^^^^^^^^
  File "/usr/lib/python3/dist-packages/flask/app.py", line 1606, in handle_http_exception
    return self.ensure_sync(handler)(e)
           ^^^^^^^^^^^^^^^^^^^^^^^^^^^^
  File "/home/Jobmanager/app/__init__.py", line 93, in page_not_found
    return app.render_template('404.html'), 404
           ^^^^^^^^^^^^^^^^^^^
AttributeError: 'Flask' object has no attribute 'render_template'
2025-03-12 13:05:15,035 [ERROR] Exception on /favicon.ico [GET]
Traceback (most recent call last):
  File "/usr/lib/python3/dist-packages/flask/app.py", line 1820, in full_dispatch_request
    rv = self.dispatch_request()
         ^^^^^^^^^^^^^^^^^^^^^^^
  File "/usr/lib/python3/dist-packages/flask/app.py", line 1785, in dispatch_request
    self.raise_routing_exception(req)
  File "/usr/lib/python3/dist-packages/flask/app.py", line 1767, in raise_routing_exception
    raise request.routing_exception  # type: ignore
    ^^^^^^^^^^^^^^^^^^^^^^^^^^^^^^^
  File "/usr/lib/python3/dist-packages/flask/ctx.py", line 351, in match_request
    result = self.url_adapter.match(return_rule=True)  # type: ignore
             ^^^^^^^^^^^^^^^^^^^^^^^^^^^^^^^^^^^^^^^^
  File "/usr/lib/python3/dist-packages/werkzeug/routing/map.py", line 624, in match
    raise NotFound() from None
werkzeug.exceptions.NotFound: 404 Not Found: The requested URL was not found on the server. If you entered the URL manually please check your spelling and try again.

During handling of the above exception, another exception occurred:

Traceback (most recent call last):
  File "/usr/lib/python3/dist-packages/flask/app.py", line 2525, in wsgi_app
    response = self.full_dispatch_request()
               ^^^^^^^^^^^^^^^^^^^^^^^^^^^^
  File "/usr/lib/python3/dist-packages/flask/app.py", line 1822, in full_dispatch_request
    rv = self.handle_user_exception(e)
         ^^^^^^^^^^^^^^^^^^^^^^^^^^^^^
  File "/usr/lib/python3/dist-packages/flask/app.py", line 1666, in handle_user_exception
    return self.handle_http_exception(e)
           ^^^^^^^^^^^^^^^^^^^^^^^^^^^^^
  File "/usr/lib/python3/dist-packages/flask/app.py", line 1606, in handle_http_exception
    return self.ensure_sync(handler)(e)
           ^^^^^^^^^^^^^^^^^^^^^^^^^^^^
  File "/home/Jobmanager/app/__init__.py", line 93, in page_not_found
    return app.render_template('404.html'), 404
           ^^^^^^^^^^^^^^^^^^^
AttributeError: 'Flask' object has no attribute 'render_template'
2025-03-12 13:26:35,936 [ERROR] Exception on /static/js/file-upload.js [GET]
Traceback (most recent call last):
  File "/usr/lib/python3/dist-packages/flask/app.py", line 1820, in full_dispatch_request
    rv = self.dispatch_request()
         ^^^^^^^^^^^^^^^^^^^^^^^
  File "/usr/lib/python3/dist-packages/flask/app.py", line 1796, in dispatch_request
    return self.ensure_sync(self.view_functions[rule.endpoint])(**view_args)
           ^^^^^^^^^^^^^^^^^^^^^^^^^^^^^^^^^^^^^^^^^^^^^^^^^^^^^^^^^^^^^^^^^
  File "/usr/lib/python3/dist-packages/flask/app.py", line 713, in <lambda>
    view_func=lambda **kw: self_ref().send_static_file(**kw),  # type: ignore # noqa: B950
                           ^^^^^^^^^^^^^^^^^^^^^^^^^^^^^^^^^
  File "/usr/lib/python3/dist-packages/flask/scaffold.py", line 331, in send_static_file
    return send_from_directory(
           ^^^^^^^^^^^^^^^^^^^^
  File "/usr/lib/python3/dist-packages/flask/helpers.py", line 590, in send_from_directory
    return werkzeug.utils.send_from_directory(  # type: ignore[return-value]
           ^^^^^^^^^^^^^^^^^^^^^^^^^^^^^^^^^^^^^^^^^^^^^^^^^^^^^^^^^^^^^^^^^
  File "/usr/lib/python3/dist-packages/werkzeug/utils.py", line 586, in send_from_directory
    raise NotFound()
werkzeug.exceptions.NotFound: 404 Not Found: The requested URL was not found on the server. If you entered the URL manually please check your spelling and try again.

During handling of the above exception, another exception occurred:

Traceback (most recent call last):
  File "/usr/lib/python3/dist-packages/flask/app.py", line 2525, in wsgi_app
    response = self.full_dispatch_request()
               ^^^^^^^^^^^^^^^^^^^^^^^^^^^^
  File "/usr/lib/python3/dist-packages/flask/app.py", line 1822, in full_dispatch_request
    rv = self.handle_user_exception(e)
         ^^^^^^^^^^^^^^^^^^^^^^^^^^^^^
  File "/usr/lib/python3/dist-packages/flask/app.py", line 1666, in handle_user_exception
    return self.handle_http_exception(e)
           ^^^^^^^^^^^^^^^^^^^^^^^^^^^^^
  File "/usr/lib/python3/dist-packages/flask/app.py", line 1606, in handle_http_exception
    return self.ensure_sync(handler)(e)
           ^^^^^^^^^^^^^^^^^^^^^^^^^^^^
  File "/home/Jobmanager/app/__init__.py", line 93, in page_not_found
    return app.render_template('404.html'), 404
           ^^^^^^^^^^^^^^^^^^^
AttributeError: 'Flask' object has no attribute 'render_template'
2025-03-12 13:26:41,671 [ERROR] Exception on /static/js/file-upload.js [GET]
Traceback (most recent call last):
  File "/usr/lib/python3/dist-packages/flask/app.py", line 1820, in full_dispatch_request
    rv = self.dispatch_request()
         ^^^^^^^^^^^^^^^^^^^^^^^
  File "/usr/lib/python3/dist-packages/flask/app.py", line 1796, in dispatch_request
    return self.ensure_sync(self.view_functions[rule.endpoint])(**view_args)
           ^^^^^^^^^^^^^^^^^^^^^^^^^^^^^^^^^^^^^^^^^^^^^^^^^^^^^^^^^^^^^^^^^
  File "/usr/lib/python3/dist-packages/flask/app.py", line 713, in <lambda>
    view_func=lambda **kw: self_ref().send_static_file(**kw),  # type: ignore # noqa: B950
                           ^^^^^^^^^^^^^^^^^^^^^^^^^^^^^^^^^
  File "/usr/lib/python3/dist-packages/flask/scaffold.py", line 331, in send_static_file
    return send_from_directory(
           ^^^^^^^^^^^^^^^^^^^^
  File "/usr/lib/python3/dist-packages/flask/helpers.py", line 590, in send_from_directory
    return werkzeug.utils.send_from_directory(  # type: ignore[return-value]
           ^^^^^^^^^^^^^^^^^^^^^^^^^^^^^^^^^^^^^^^^^^^^^^^^^^^^^^^^^^^^^^^^^
  File "/usr/lib/python3/dist-packages/werkzeug/utils.py", line 586, in send_from_directory
    raise NotFound()
werkzeug.exceptions.NotFound: 404 Not Found: The requested URL was not found on the server. If you entered the URL manually please check your spelling and try again.

During handling of the above exception, another exception occurred:

Traceback (most recent call last):
  File "/usr/lib/python3/dist-packages/flask/app.py", line 2525, in wsgi_app
    response = self.full_dispatch_request()
               ^^^^^^^^^^^^^^^^^^^^^^^^^^^^
  File "/usr/lib/python3/dist-packages/flask/app.py", line 1822, in full_dispatch_request
    rv = self.handle_user_exception(e)
         ^^^^^^^^^^^^^^^^^^^^^^^^^^^^^
  File "/usr/lib/python3/dist-packages/flask/app.py", line 1666, in handle_user_exception
    return self.handle_http_exception(e)
           ^^^^^^^^^^^^^^^^^^^^^^^^^^^^^
  File "/usr/lib/python3/dist-packages/flask/app.py", line 1606, in handle_http_exception
    return self.ensure_sync(handler)(e)
           ^^^^^^^^^^^^^^^^^^^^^^^^^^^^
  File "/home/Jobmanager/app/__init__.py", line 93, in page_not_found
    return app.render_template('404.html'), 404
           ^^^^^^^^^^^^^^^^^^^
AttributeError: 'Flask' object has no attribute 'render_template'
2025-03-12 13:41:38,481 [INFO] Root path: /home/Jobmanager
2025-03-12 13:41:38,481 [INFO] Current working directory: /home/Jobmanager
2025-03-12 13:41:38,481 [INFO] Instance path: /home/Jobmanager/instance
2025-03-12 13:41:38,481 [INFO] Creating full backup at: /home/Jobmanager/backups/jobmanager_backup_20250312_1341.zip
2025-03-12 13:41:38,481 [INFO] Adding file: /home/Jobmanager/run.py
2025-03-12 13:41:38,482 [INFO] Adding file: /home/Jobmanager/init_db.py
2025-03-12 13:41:38,482 [INFO] Adding to zip: app/db.py
2025-03-12 13:41:38,482 [INFO] Adding to zip: app/__init__.py
2025-03-12 13:41:38,483 [INFO] Adding to zip: app/schema.sql
2025-03-12 13:41:38,483 [INFO] Adding to zip: app/routes/image_routes.py
2025-03-12 13:41:38,484 [INFO] Adding to zip: app/routes/system_routes.py
2025-03-12 13:41:38,484 [INFO] Adding to zip: app/routes/__init__.py
2025-03-12 13:41:38,484 [INFO] Adding to zip: app/routes/customer_routes.py
2025-03-12 13:41:38,485 [INFO] Adding to zip: app/routes/job_routes.py
2025-03-12 13:41:38,485 [INFO] Adding to zip: app/routes/report_routes.py
2025-03-12 13:41:38,486 [INFO] Adding to zip: app/routes/timer_routes.py
2025-03-12 13:41:38,486 [INFO] Adding to zip: app/utils/date_helper.py
2025-03-12 13:41:38,487 [INFO] Adding to zip: app/utils/time_utils.py
2025-03-12 13:41:38,487 [INFO] Adding to zip: app/utils/job_utils.py
2025-03-12 13:41:38,487 [INFO] Adding to zip: app/utils/material_utils.py
2025-03-12 13:41:38,487 [INFO] Adding to zip: app/utils/timer_utils.py
2025-03-12 13:41:38,488 [INFO] Adding to zip: app/utils/__init__.py
2025-03-12 13:41:38,488 [INFO] Adding to zip: app/utils/invoice_utils.py
2025-03-12 13:41:38,488 [INFO] Adding to zip: app/utils/error_utils.py
2025-03-12 13:41:38,488 [INFO] Adding to zip: app/utils/profile_utils.py
2025-03-12 13:41:38,489 [INFO] Adding to zip: app/utils/image_utils.py
2025-03-12 13:41:38,489 [INFO] Adding to zip: app/templates/customer_form.html
2025-03-12 13:41:38,489 [INFO] Adding to zip: app/templates/quick_timer.html
2025-03-12 13:41:38,490 [INFO] Adding to zip: app/templates/system_settings.html
2025-03-12 13:41:38,490 [INFO] Adding to zip: app/templates/shared_images.html
2025-03-12 13:41:38,490 [INFO] Adding to zip: app/templates/weekly_summary.html
2025-03-12 13:41:38,491 [INFO] Adding to zip: app/templates/job_details.html
2025-03-12 13:41:38,492 [INFO] Adding to zip: app/templates/invoice.html
2025-03-12 13:41:38,492 [INFO] Adding to zip: app/templates/job_form.html
2025-03-12 13:41:38,493 [INFO] Adding to zip: app/templates/customer_list.html
2025-03-12 13:41:38,493 [INFO] Adding to zip: app/templates/500.html
2025-03-12 13:41:38,493 [INFO] Adding to zip: app/templates/base.html
2025-03-12 13:41:38,493 [INFO] Adding to zip: app/templates/profile_settings.html
2025-03-12 13:41:38,494 [INFO] Adding to zip: app/templates/job_list.html
2025-03-12 13:41:38,494 [INFO] Adding to zip: app/templates/404.html
2025-03-12 13:41:38,494 [INFO] Adding to zip: app/static/favicon.ico
2025-03-12 13:41:38,495 [INFO] Adding to zip: app/static/qr-quick_timer.svg
2025-03-12 13:41:38,495 [INFO] Adding to zip: app/static/js/file_upload.js
2025-03-12 13:41:38,495 [INFO] Adding to zip: app/static/css/styles.css
2025-03-12 13:41:38,496 [INFO] Adding to zip: app/static/css/file-upload.css
2025-03-12 13:41:38,497 [INFO] Adding to zip: instance/user_profile.json
2025-03-12 13:41:38,497 [INFO] Full backup created at: /home/Jobmanager/backups/jobmanager_backup_20250312_1341.zip
2025-03-12 13:41:38,497 [INFO] Backup file exists: True
2025-03-12 15:08:35,420 [INFO] Starting timer for job 48
2025-03-12 15:08:35,420 [INFO] Stopping all active timers
2025-03-12 15:08:38,607 [ERROR] Exception on /static/js/file-upload.js [GET]
Traceback (most recent call last):
  File "/usr/lib/python3/dist-packages/flask/app.py", line 1820, in full_dispatch_request
    rv = self.dispatch_request()
         ^^^^^^^^^^^^^^^^^^^^^^^
  File "/usr/lib/python3/dist-packages/flask/app.py", line 1796, in dispatch_request
    return self.ensure_sync(self.view_functions[rule.endpoint])(**view_args)
           ^^^^^^^^^^^^^^^^^^^^^^^^^^^^^^^^^^^^^^^^^^^^^^^^^^^^^^^^^^^^^^^^^
  File "/usr/lib/python3/dist-packages/flask/app.py", line 713, in <lambda>
    view_func=lambda **kw: self_ref().send_static_file(**kw),  # type: ignore # noqa: B950
                           ^^^^^^^^^^^^^^^^^^^^^^^^^^^^^^^^^
  File "/usr/lib/python3/dist-packages/flask/scaffold.py", line 331, in send_static_file
    return send_from_directory(
           ^^^^^^^^^^^^^^^^^^^^
  File "/usr/lib/python3/dist-packages/flask/helpers.py", line 590, in send_from_directory
    return werkzeug.utils.send_from_directory(  # type: ignore[return-value]
           ^^^^^^^^^^^^^^^^^^^^^^^^^^^^^^^^^^^^^^^^^^^^^^^^^^^^^^^^^^^^^^^^^
  File "/usr/lib/python3/dist-packages/werkzeug/utils.py", line 586, in send_from_directory
    raise NotFound()
werkzeug.exceptions.NotFound: 404 Not Found: The requested URL was not found on the server. If you entered the URL manually please check your spelling and try again.

During handling of the above exception, another exception occurred:

Traceback (most recent call last):
  File "/usr/lib/python3/dist-packages/flask/app.py", line 2525, in wsgi_app
    response = self.full_dispatch_request()
               ^^^^^^^^^^^^^^^^^^^^^^^^^^^^
  File "/usr/lib/python3/dist-packages/flask/app.py", line 1822, in full_dispatch_request
    rv = self.handle_user_exception(e)
         ^^^^^^^^^^^^^^^^^^^^^^^^^^^^^
  File "/usr/lib/python3/dist-packages/flask/app.py", line 1666, in handle_user_exception
    return self.handle_http_exception(e)
           ^^^^^^^^^^^^^^^^^^^^^^^^^^^^^
  File "/usr/lib/python3/dist-packages/flask/app.py", line 1606, in handle_http_exception
    return self.ensure_sync(handler)(e)
           ^^^^^^^^^^^^^^^^^^^^^^^^^^^^
  File "/home/Jobmanager/app/__init__.py", line 93, in page_not_found
    return app.render_template('404.html'), 404
           ^^^^^^^^^^^^^^^^^^^
AttributeError: 'Flask' object has no attribute 'render_template'
2025-03-12 15:09:47,456 [ERROR] Exception on /static/js/file-upload.js [GET]
Traceback (most recent call last):
  File "/usr/lib/python3/dist-packages/flask/app.py", line 1820, in full_dispatch_request
    rv = self.dispatch_request()
         ^^^^^^^^^^^^^^^^^^^^^^^
  File "/usr/lib/python3/dist-packages/flask/app.py", line 1796, in dispatch_request
    return self.ensure_sync(self.view_functions[rule.endpoint])(**view_args)
           ^^^^^^^^^^^^^^^^^^^^^^^^^^^^^^^^^^^^^^^^^^^^^^^^^^^^^^^^^^^^^^^^^
  File "/usr/lib/python3/dist-packages/flask/app.py", line 713, in <lambda>
    view_func=lambda **kw: self_ref().send_static_file(**kw),  # type: ignore # noqa: B950
                           ^^^^^^^^^^^^^^^^^^^^^^^^^^^^^^^^^
  File "/usr/lib/python3/dist-packages/flask/scaffold.py", line 331, in send_static_file
    return send_from_directory(
           ^^^^^^^^^^^^^^^^^^^^
  File "/usr/lib/python3/dist-packages/flask/helpers.py", line 590, in send_from_directory
    return werkzeug.utils.send_from_directory(  # type: ignore[return-value]
           ^^^^^^^^^^^^^^^^^^^^^^^^^^^^^^^^^^^^^^^^^^^^^^^^^^^^^^^^^^^^^^^^^
  File "/usr/lib/python3/dist-packages/werkzeug/utils.py", line 586, in send_from_directory
    raise NotFound()
werkzeug.exceptions.NotFound: 404 Not Found: The requested URL was not found on the server. If you entered the URL manually please check your spelling and try again.

During handling of the above exception, another exception occurred:

Traceback (most recent call last):
  File "/usr/lib/python3/dist-packages/flask/app.py", line 2525, in wsgi_app
    response = self.full_dispatch_request()
               ^^^^^^^^^^^^^^^^^^^^^^^^^^^^
  File "/usr/lib/python3/dist-packages/flask/app.py", line 1822, in full_dispatch_request
    rv = self.handle_user_exception(e)
         ^^^^^^^^^^^^^^^^^^^^^^^^^^^^^
  File "/usr/lib/python3/dist-packages/flask/app.py", line 1666, in handle_user_exception
    return self.handle_http_exception(e)
           ^^^^^^^^^^^^^^^^^^^^^^^^^^^^^
  File "/usr/lib/python3/dist-packages/flask/app.py", line 1606, in handle_http_exception
    return self.ensure_sync(handler)(e)
           ^^^^^^^^^^^^^^^^^^^^^^^^^^^^
  File "/home/Jobmanager/app/__init__.py", line 93, in page_not_found
    return app.render_template('404.html'), 404
           ^^^^^^^^^^^^^^^^^^^
AttributeError: 'Flask' object has no attribute 'render_template'
2025-03-12 15:10:04,937 [ERROR] Exception on /static/js/file-upload.js [GET]
Traceback (most recent call last):
  File "/usr/lib/python3/dist-packages/flask/app.py", line 1820, in full_dispatch_request
    rv = self.dispatch_request()
         ^^^^^^^^^^^^^^^^^^^^^^^
  File "/usr/lib/python3/dist-packages/flask/app.py", line 1796, in dispatch_request
    return self.ensure_sync(self.view_functions[rule.endpoint])(**view_args)
           ^^^^^^^^^^^^^^^^^^^^^^^^^^^^^^^^^^^^^^^^^^^^^^^^^^^^^^^^^^^^^^^^^
  File "/usr/lib/python3/dist-packages/flask/app.py", line 713, in <lambda>
    view_func=lambda **kw: self_ref().send_static_file(**kw),  # type: ignore # noqa: B950
                           ^^^^^^^^^^^^^^^^^^^^^^^^^^^^^^^^^
  File "/usr/lib/python3/dist-packages/flask/scaffold.py", line 331, in send_static_file
    return send_from_directory(
           ^^^^^^^^^^^^^^^^^^^^
  File "/usr/lib/python3/dist-packages/flask/helpers.py", line 590, in send_from_directory
    return werkzeug.utils.send_from_directory(  # type: ignore[return-value]
           ^^^^^^^^^^^^^^^^^^^^^^^^^^^^^^^^^^^^^^^^^^^^^^^^^^^^^^^^^^^^^^^^^
  File "/usr/lib/python3/dist-packages/werkzeug/utils.py", line 586, in send_from_directory
    raise NotFound()
werkzeug.exceptions.NotFound: 404 Not Found: The requested URL was not found on the server. If you entered the URL manually please check your spelling and try again.

During handling of the above exception, another exception occurred:

Traceback (most recent call last):
  File "/usr/lib/python3/dist-packages/flask/app.py", line 2525, in wsgi_app
    response = self.full_dispatch_request()
               ^^^^^^^^^^^^^^^^^^^^^^^^^^^^
  File "/usr/lib/python3/dist-packages/flask/app.py", line 1822, in full_dispatch_request
    rv = self.handle_user_exception(e)
         ^^^^^^^^^^^^^^^^^^^^^^^^^^^^^
  File "/usr/lib/python3/dist-packages/flask/app.py", line 1666, in handle_user_exception
    return self.handle_http_exception(e)
           ^^^^^^^^^^^^^^^^^^^^^^^^^^^^^
  File "/usr/lib/python3/dist-packages/flask/app.py", line 1606, in handle_http_exception
    return self.ensure_sync(handler)(e)
           ^^^^^^^^^^^^^^^^^^^^^^^^^^^^
  File "/home/Jobmanager/app/__init__.py", line 93, in page_not_found
    return app.render_template('404.html'), 404
           ^^^^^^^^^^^^^^^^^^^
AttributeError: 'Flask' object has no attribute 'render_template'
2025-03-12 15:10:30,305 [ERROR] Exception on /static/js/file-upload.js [GET]
Traceback (most recent call last):
  File "/usr/lib/python3/dist-packages/flask/app.py", line 1820, in full_dispatch_request
    rv = self.dispatch_request()
         ^^^^^^^^^^^^^^^^^^^^^^^
  File "/usr/lib/python3/dist-packages/flask/app.py", line 1796, in dispatch_request
    return self.ensure_sync(self.view_functions[rule.endpoint])(**view_args)
           ^^^^^^^^^^^^^^^^^^^^^^^^^^^^^^^^^^^^^^^^^^^^^^^^^^^^^^^^^^^^^^^^^
  File "/usr/lib/python3/dist-packages/flask/app.py", line 713, in <lambda>
    view_func=lambda **kw: self_ref().send_static_file(**kw),  # type: ignore # noqa: B950
                           ^^^^^^^^^^^^^^^^^^^^^^^^^^^^^^^^^
  File "/usr/lib/python3/dist-packages/flask/scaffold.py", line 331, in send_static_file
    return send_from_directory(
           ^^^^^^^^^^^^^^^^^^^^
  File "/usr/lib/python3/dist-packages/flask/helpers.py", line 590, in send_from_directory
    return werkzeug.utils.send_from_directory(  # type: ignore[return-value]
           ^^^^^^^^^^^^^^^^^^^^^^^^^^^^^^^^^^^^^^^^^^^^^^^^^^^^^^^^^^^^^^^^^
  File "/usr/lib/python3/dist-packages/werkzeug/utils.py", line 586, in send_from_directory
    raise NotFound()
werkzeug.exceptions.NotFound: 404 Not Found: The requested URL was not found on the server. If you entered the URL manually please check your spelling and try again.

During handling of the above exception, another exception occurred:

Traceback (most recent call last):
  File "/usr/lib/python3/dist-packages/flask/app.py", line 2525, in wsgi_app
    response = self.full_dispatch_request()
               ^^^^^^^^^^^^^^^^^^^^^^^^^^^^
  File "/usr/lib/python3/dist-packages/flask/app.py", line 1822, in full_dispatch_request
    rv = self.handle_user_exception(e)
         ^^^^^^^^^^^^^^^^^^^^^^^^^^^^^
  File "/usr/lib/python3/dist-packages/flask/app.py", line 1666, in handle_user_exception
    return self.handle_http_exception(e)
           ^^^^^^^^^^^^^^^^^^^^^^^^^^^^^
  File "/usr/lib/python3/dist-packages/flask/app.py", line 1606, in handle_http_exception
    return self.ensure_sync(handler)(e)
           ^^^^^^^^^^^^^^^^^^^^^^^^^^^^
  File "/home/Jobmanager/app/__init__.py", line 93, in page_not_found
    return app.render_template('404.html'), 404
           ^^^^^^^^^^^^^^^^^^^
AttributeError: 'Flask' object has no attribute 'render_template'
2025-03-12 15:10:50,855 [ERROR] Exception on /static/js/file-upload.js [GET]
Traceback (most recent call last):
  File "/usr/lib/python3/dist-packages/flask/app.py", line 1820, in full_dispatch_request
    rv = self.dispatch_request()
         ^^^^^^^^^^^^^^^^^^^^^^^
  File "/usr/lib/python3/dist-packages/flask/app.py", line 1796, in dispatch_request
    return self.ensure_sync(self.view_functions[rule.endpoint])(**view_args)
           ^^^^^^^^^^^^^^^^^^^^^^^^^^^^^^^^^^^^^^^^^^^^^^^^^^^^^^^^^^^^^^^^^
  File "/usr/lib/python3/dist-packages/flask/app.py", line 713, in <lambda>
    view_func=lambda **kw: self_ref().send_static_file(**kw),  # type: ignore # noqa: B950
                           ^^^^^^^^^^^^^^^^^^^^^^^^^^^^^^^^^
  File "/usr/lib/python3/dist-packages/flask/scaffold.py", line 331, in send_static_file
    return send_from_directory(
           ^^^^^^^^^^^^^^^^^^^^
  File "/usr/lib/python3/dist-packages/flask/helpers.py", line 590, in send_from_directory
    return werkzeug.utils.send_from_directory(  # type: ignore[return-value]
           ^^^^^^^^^^^^^^^^^^^^^^^^^^^^^^^^^^^^^^^^^^^^^^^^^^^^^^^^^^^^^^^^^
  File "/usr/lib/python3/dist-packages/werkzeug/utils.py", line 586, in send_from_directory
    raise NotFound()
werkzeug.exceptions.NotFound: 404 Not Found: The requested URL was not found on the server. If you entered the URL manually please check your spelling and try again.

During handling of the above exception, another exception occurred:

Traceback (most recent call last):
  File "/usr/lib/python3/dist-packages/flask/app.py", line 2525, in wsgi_app
    response = self.full_dispatch_request()
               ^^^^^^^^^^^^^^^^^^^^^^^^^^^^
  File "/usr/lib/python3/dist-packages/flask/app.py", line 1822, in full_dispatch_request
    rv = self.handle_user_exception(e)
         ^^^^^^^^^^^^^^^^^^^^^^^^^^^^^
  File "/usr/lib/python3/dist-packages/flask/app.py", line 1666, in handle_user_exception
    return self.handle_http_exception(e)
           ^^^^^^^^^^^^^^^^^^^^^^^^^^^^^
  File "/usr/lib/python3/dist-packages/flask/app.py", line 1606, in handle_http_exception
    return self.ensure_sync(handler)(e)
           ^^^^^^^^^^^^^^^^^^^^^^^^^^^^
  File "/home/Jobmanager/app/__init__.py", line 93, in page_not_found
    return app.render_template('404.html'), 404
           ^^^^^^^^^^^^^^^^^^^
AttributeError: 'Flask' object has no attribute 'render_template'
2025-03-12 15:11:49,217 [ERROR] Exception on /static/js/file-upload.js [GET]
Traceback (most recent call last):
  File "/usr/lib/python3/dist-packages/flask/app.py", line 1820, in full_dispatch_request
    rv = self.dispatch_request()
         ^^^^^^^^^^^^^^^^^^^^^^^
  File "/usr/lib/python3/dist-packages/flask/app.py", line 1796, in dispatch_request
    return self.ensure_sync(self.view_functions[rule.endpoint])(**view_args)
           ^^^^^^^^^^^^^^^^^^^^^^^^^^^^^^^^^^^^^^^^^^^^^^^^^^^^^^^^^^^^^^^^^
  File "/usr/lib/python3/dist-packages/flask/app.py", line 713, in <lambda>
    view_func=lambda **kw: self_ref().send_static_file(**kw),  # type: ignore # noqa: B950
                           ^^^^^^^^^^^^^^^^^^^^^^^^^^^^^^^^^
  File "/usr/lib/python3/dist-packages/flask/scaffold.py", line 331, in send_static_file
    return send_from_directory(
           ^^^^^^^^^^^^^^^^^^^^
  File "/usr/lib/python3/dist-packages/flask/helpers.py", line 590, in send_from_directory
    return werkzeug.utils.send_from_directory(  # type: ignore[return-value]
           ^^^^^^^^^^^^^^^^^^^^^^^^^^^^^^^^^^^^^^^^^^^^^^^^^^^^^^^^^^^^^^^^^
  File "/usr/lib/python3/dist-packages/werkzeug/utils.py", line 586, in send_from_directory
    raise NotFound()
werkzeug.exceptions.NotFound: 404 Not Found: The requested URL was not found on the server. If you entered the URL manually please check your spelling and try again.

During handling of the above exception, another exception occurred:

Traceback (most recent call last):
  File "/usr/lib/python3/dist-packages/flask/app.py", line 2525, in wsgi_app
    response = self.full_dispatch_request()
               ^^^^^^^^^^^^^^^^^^^^^^^^^^^^
  File "/usr/lib/python3/dist-packages/flask/app.py", line 1822, in full_dispatch_request
    rv = self.handle_user_exception(e)
         ^^^^^^^^^^^^^^^^^^^^^^^^^^^^^
  File "/usr/lib/python3/dist-packages/flask/app.py", line 1666, in handle_user_exception
    return self.handle_http_exception(e)
           ^^^^^^^^^^^^^^^^^^^^^^^^^^^^^
  File "/usr/lib/python3/dist-packages/flask/app.py", line 1606, in handle_http_exception
    return self.ensure_sync(handler)(e)
           ^^^^^^^^^^^^^^^^^^^^^^^^^^^^
  File "/home/Jobmanager/app/__init__.py", line 93, in page_not_found
    return app.render_template('404.html'), 404
           ^^^^^^^^^^^^^^^^^^^
AttributeError: 'Flask' object has no attribute 'render_template'
2025-03-12 15:12:08,886 [ERROR] Exception on /static/js/file-upload.js [GET]
Traceback (most recent call last):
  File "/usr/lib/python3/dist-packages/flask/app.py", line 1820, in full_dispatch_request
    rv = self.dispatch_request()
         ^^^^^^^^^^^^^^^^^^^^^^^
  File "/usr/lib/python3/dist-packages/flask/app.py", line 1796, in dispatch_request
    return self.ensure_sync(self.view_functions[rule.endpoint])(**view_args)
           ^^^^^^^^^^^^^^^^^^^^^^^^^^^^^^^^^^^^^^^^^^^^^^^^^^^^^^^^^^^^^^^^^
  File "/usr/lib/python3/dist-packages/flask/app.py", line 713, in <lambda>
    view_func=lambda **kw: self_ref().send_static_file(**kw),  # type: ignore # noqa: B950
                           ^^^^^^^^^^^^^^^^^^^^^^^^^^^^^^^^^
  File "/usr/lib/python3/dist-packages/flask/scaffold.py", line 331, in send_static_file
    return send_from_directory(
           ^^^^^^^^^^^^^^^^^^^^
  File "/usr/lib/python3/dist-packages/flask/helpers.py", line 590, in send_from_directory
    return werkzeug.utils.send_from_directory(  # type: ignore[return-value]
           ^^^^^^^^^^^^^^^^^^^^^^^^^^^^^^^^^^^^^^^^^^^^^^^^^^^^^^^^^^^^^^^^^
  File "/usr/lib/python3/dist-packages/werkzeug/utils.py", line 586, in send_from_directory
    raise NotFound()
werkzeug.exceptions.NotFound: 404 Not Found: The requested URL was not found on the server. If you entered the URL manually please check your spelling and try again.

During handling of the above exception, another exception occurred:

Traceback (most recent call last):
  File "/usr/lib/python3/dist-packages/flask/app.py", line 2525, in wsgi_app
    response = self.full_dispatch_request()
               ^^^^^^^^^^^^^^^^^^^^^^^^^^^^
  File "/usr/lib/python3/dist-packages/flask/app.py", line 1822, in full_dispatch_request
    rv = self.handle_user_exception(e)
         ^^^^^^^^^^^^^^^^^^^^^^^^^^^^^
  File "/usr/lib/python3/dist-packages/flask/app.py", line 1666, in handle_user_exception
    return self.handle_http_exception(e)
           ^^^^^^^^^^^^^^^^^^^^^^^^^^^^^
  File "/usr/lib/python3/dist-packages/flask/app.py", line 1606, in handle_http_exception
    return self.ensure_sync(handler)(e)
           ^^^^^^^^^^^^^^^^^^^^^^^^^^^^
  File "/home/Jobmanager/app/__init__.py", line 93, in page_not_found
    return app.render_template('404.html'), 404
           ^^^^^^^^^^^^^^^^^^^
AttributeError: 'Flask' object has no attribute 'render_template'
2025-03-12 15:12:43,446 [ERROR] Exception on /static/js/file-upload.js [GET]
Traceback (most recent call last):
  File "/usr/lib/python3/dist-packages/flask/app.py", line 1820, in full_dispatch_request
    rv = self.dispatch_request()
         ^^^^^^^^^^^^^^^^^^^^^^^
  File "/usr/lib/python3/dist-packages/flask/app.py", line 1796, in dispatch_request
    return self.ensure_sync(self.view_functions[rule.endpoint])(**view_args)
           ^^^^^^^^^^^^^^^^^^^^^^^^^^^^^^^^^^^^^^^^^^^^^^^^^^^^^^^^^^^^^^^^^
  File "/usr/lib/python3/dist-packages/flask/app.py", line 713, in <lambda>
    view_func=lambda **kw: self_ref().send_static_file(**kw),  # type: ignore # noqa: B950
                           ^^^^^^^^^^^^^^^^^^^^^^^^^^^^^^^^^
  File "/usr/lib/python3/dist-packages/flask/scaffold.py", line 331, in send_static_file
    return send_from_directory(
           ^^^^^^^^^^^^^^^^^^^^
  File "/usr/lib/python3/dist-packages/flask/helpers.py", line 590, in send_from_directory
    return werkzeug.utils.send_from_directory(  # type: ignore[return-value]
           ^^^^^^^^^^^^^^^^^^^^^^^^^^^^^^^^^^^^^^^^^^^^^^^^^^^^^^^^^^^^^^^^^
  File "/usr/lib/python3/dist-packages/werkzeug/utils.py", line 586, in send_from_directory
    raise NotFound()
werkzeug.exceptions.NotFound: 404 Not Found: The requested URL was not found on the server. If you entered the URL manually please check your spelling and try again.

During handling of the above exception, another exception occurred:

Traceback (most recent call last):
  File "/usr/lib/python3/dist-packages/flask/app.py", line 2525, in wsgi_app
    response = self.full_dispatch_request()
               ^^^^^^^^^^^^^^^^^^^^^^^^^^^^
  File "/usr/lib/python3/dist-packages/flask/app.py", line 1822, in full_dispatch_request
    rv = self.handle_user_exception(e)
         ^^^^^^^^^^^^^^^^^^^^^^^^^^^^^
  File "/usr/lib/python3/dist-packages/flask/app.py", line 1666, in handle_user_exception
    return self.handle_http_exception(e)
           ^^^^^^^^^^^^^^^^^^^^^^^^^^^^^
  File "/usr/lib/python3/dist-packages/flask/app.py", line 1606, in handle_http_exception
    return self.ensure_sync(handler)(e)
           ^^^^^^^^^^^^^^^^^^^^^^^^^^^^
  File "/home/Jobmanager/app/__init__.py", line 93, in page_not_found
    return app.render_template('404.html'), 404
           ^^^^^^^^^^^^^^^^^^^
AttributeError: 'Flask' object has no attribute 'render_template'
2025-03-12 15:13:56,429 [ERROR] Exception on /static/js/file-upload.js [GET]
Traceback (most recent call last):
  File "/usr/lib/python3/dist-packages/flask/app.py", line 1820, in full_dispatch_request
    rv = self.dispatch_request()
         ^^^^^^^^^^^^^^^^^^^^^^^
  File "/usr/lib/python3/dist-packages/flask/app.py", line 1796, in dispatch_request
    return self.ensure_sync(self.view_functions[rule.endpoint])(**view_args)
           ^^^^^^^^^^^^^^^^^^^^^^^^^^^^^^^^^^^^^^^^^^^^^^^^^^^^^^^^^^^^^^^^^
  File "/usr/lib/python3/dist-packages/flask/app.py", line 713, in <lambda>
    view_func=lambda **kw: self_ref().send_static_file(**kw),  # type: ignore # noqa: B950
                           ^^^^^^^^^^^^^^^^^^^^^^^^^^^^^^^^^
  File "/usr/lib/python3/dist-packages/flask/scaffold.py", line 331, in send_static_file
    return send_from_directory(
           ^^^^^^^^^^^^^^^^^^^^
  File "/usr/lib/python3/dist-packages/flask/helpers.py", line 590, in send_from_directory
    return werkzeug.utils.send_from_directory(  # type: ignore[return-value]
           ^^^^^^^^^^^^^^^^^^^^^^^^^^^^^^^^^^^^^^^^^^^^^^^^^^^^^^^^^^^^^^^^^
  File "/usr/lib/python3/dist-packages/werkzeug/utils.py", line 586, in send_from_directory
    raise NotFound()
werkzeug.exceptions.NotFound: 404 Not Found: The requested URL was not found on the server. If you entered the URL manually please check your spelling and try again.

During handling of the above exception, another exception occurred:

Traceback (most recent call last):
  File "/usr/lib/python3/dist-packages/flask/app.py", line 2525, in wsgi_app
    response = self.full_dispatch_request()
               ^^^^^^^^^^^^^^^^^^^^^^^^^^^^
  File "/usr/lib/python3/dist-packages/flask/app.py", line 1822, in full_dispatch_request
    rv = self.handle_user_exception(e)
         ^^^^^^^^^^^^^^^^^^^^^^^^^^^^^
  File "/usr/lib/python3/dist-packages/flask/app.py", line 1666, in handle_user_exception
    return self.handle_http_exception(e)
           ^^^^^^^^^^^^^^^^^^^^^^^^^^^^^
  File "/usr/lib/python3/dist-packages/flask/app.py", line 1606, in handle_http_exception
    return self.ensure_sync(handler)(e)
           ^^^^^^^^^^^^^^^^^^^^^^^^^^^^
  File "/home/Jobmanager/app/__init__.py", line 93, in page_not_found
    return app.render_template('404.html'), 404
           ^^^^^^^^^^^^^^^^^^^
AttributeError: 'Flask' object has no attribute 'render_template'
2025-03-12 15:14:46,261 [ERROR] Exception on /static/js/file-upload.js [GET]
Traceback (most recent call last):
  File "/usr/lib/python3/dist-packages/flask/app.py", line 1820, in full_dispatch_request
    rv = self.dispatch_request()
         ^^^^^^^^^^^^^^^^^^^^^^^
  File "/usr/lib/python3/dist-packages/flask/app.py", line 1796, in dispatch_request
    return self.ensure_sync(self.view_functions[rule.endpoint])(**view_args)
           ^^^^^^^^^^^^^^^^^^^^^^^^^^^^^^^^^^^^^^^^^^^^^^^^^^^^^^^^^^^^^^^^^
  File "/usr/lib/python3/dist-packages/flask/app.py", line 713, in <lambda>
    view_func=lambda **kw: self_ref().send_static_file(**kw),  # type: ignore # noqa: B950
                           ^^^^^^^^^^^^^^^^^^^^^^^^^^^^^^^^^
  File "/usr/lib/python3/dist-packages/flask/scaffold.py", line 331, in send_static_file
    return send_from_directory(
           ^^^^^^^^^^^^^^^^^^^^
  File "/usr/lib/python3/dist-packages/flask/helpers.py", line 590, in send_from_directory
    return werkzeug.utils.send_from_directory(  # type: ignore[return-value]
           ^^^^^^^^^^^^^^^^^^^^^^^^^^^^^^^^^^^^^^^^^^^^^^^^^^^^^^^^^^^^^^^^^
  File "/usr/lib/python3/dist-packages/werkzeug/utils.py", line 586, in send_from_directory
    raise NotFound()
werkzeug.exceptions.NotFound: 404 Not Found: The requested URL was not found on the server. If you entered the URL manually please check your spelling and try again.

During handling of the above exception, another exception occurred:

Traceback (most recent call last):
  File "/usr/lib/python3/dist-packages/flask/app.py", line 2525, in wsgi_app
    response = self.full_dispatch_request()
               ^^^^^^^^^^^^^^^^^^^^^^^^^^^^
  File "/usr/lib/python3/dist-packages/flask/app.py", line 1822, in full_dispatch_request
    rv = self.handle_user_exception(e)
         ^^^^^^^^^^^^^^^^^^^^^^^^^^^^^
  File "/usr/lib/python3/dist-packages/flask/app.py", line 1666, in handle_user_exception
    return self.handle_http_exception(e)
           ^^^^^^^^^^^^^^^^^^^^^^^^^^^^^
  File "/usr/lib/python3/dist-packages/flask/app.py", line 1606, in handle_http_exception
    return self.ensure_sync(handler)(e)
           ^^^^^^^^^^^^^^^^^^^^^^^^^^^^
  File "/home/Jobmanager/app/__init__.py", line 93, in page_not_found
    return app.render_template('404.html'), 404
           ^^^^^^^^^^^^^^^^^^^
AttributeError: 'Flask' object has no attribute 'render_template'
2025-03-12 15:14:51,340 [INFO] Weekly summary request - selected_week: None, show_all: False
2025-03-12 15:14:51,340 [INFO] No week selected, using current week: 2025-W11
2025-03-12 15:14:51,340 [INFO] Fetching available weeks
2025-03-12 15:14:51,340 [INFO] Found 36 distinct dates with time entries
2025-03-12 15:14:51,340 [INFO] Processed 6 unique weeks
2025-03-12 15:14:51,340 [INFO] Final view settings - selected_week: 2025-W11, show_all: False
2025-03-12 15:14:51,341 [INFO] Found 20 time entries for week 2025-W11
2025-03-12 15:14:55,912 [ERROR] Exception on /static/js/file-upload.js [GET]
Traceback (most recent call last):
  File "/usr/lib/python3/dist-packages/flask/app.py", line 1820, in full_dispatch_request
    rv = self.dispatch_request()
         ^^^^^^^^^^^^^^^^^^^^^^^
  File "/usr/lib/python3/dist-packages/flask/app.py", line 1796, in dispatch_request
    return self.ensure_sync(self.view_functions[rule.endpoint])(**view_args)
           ^^^^^^^^^^^^^^^^^^^^^^^^^^^^^^^^^^^^^^^^^^^^^^^^^^^^^^^^^^^^^^^^^
  File "/usr/lib/python3/dist-packages/flask/app.py", line 713, in <lambda>
    view_func=lambda **kw: self_ref().send_static_file(**kw),  # type: ignore # noqa: B950
                           ^^^^^^^^^^^^^^^^^^^^^^^^^^^^^^^^^
  File "/usr/lib/python3/dist-packages/flask/scaffold.py", line 331, in send_static_file
    return send_from_directory(
           ^^^^^^^^^^^^^^^^^^^^
  File "/usr/lib/python3/dist-packages/flask/helpers.py", line 590, in send_from_directory
    return werkzeug.utils.send_from_directory(  # type: ignore[return-value]
           ^^^^^^^^^^^^^^^^^^^^^^^^^^^^^^^^^^^^^^^^^^^^^^^^^^^^^^^^^^^^^^^^^
  File "/usr/lib/python3/dist-packages/werkzeug/utils.py", line 586, in send_from_directory
    raise NotFound()
werkzeug.exceptions.NotFound: 404 Not Found: The requested URL was not found on the server. If you entered the URL manually please check your spelling and try again.

During handling of the above exception, another exception occurred:

Traceback (most recent call last):
  File "/usr/lib/python3/dist-packages/flask/app.py", line 2525, in wsgi_app
    response = self.full_dispatch_request()
               ^^^^^^^^^^^^^^^^^^^^^^^^^^^^
  File "/usr/lib/python3/dist-packages/flask/app.py", line 1822, in full_dispatch_request
    rv = self.handle_user_exception(e)
         ^^^^^^^^^^^^^^^^^^^^^^^^^^^^^
  File "/usr/lib/python3/dist-packages/flask/app.py", line 1666, in handle_user_exception
    return self.handle_http_exception(e)
           ^^^^^^^^^^^^^^^^^^^^^^^^^^^^^
  File "/usr/lib/python3/dist-packages/flask/app.py", line 1606, in handle_http_exception
    return self.ensure_sync(handler)(e)
           ^^^^^^^^^^^^^^^^^^^^^^^^^^^^
  File "/home/Jobmanager/app/__init__.py", line 93, in page_not_found
    return app.render_template('404.html'), 404
           ^^^^^^^^^^^^^^^^^^^
AttributeError: 'Flask' object has no attribute 'render_template'
2025-03-12 15:18:45,081 [INFO] Weekly summary request - selected_week: None, show_all: False
2025-03-12 15:18:45,081 [INFO] No week selected, using current week: 2025-W11
2025-03-12 15:18:45,081 [INFO] Fetching available weeks
2025-03-12 15:18:45,082 [INFO] Found 36 distinct dates with time entries
2025-03-12 15:18:45,082 [INFO] Processed 6 unique weeks
2025-03-12 15:18:45,082 [INFO] Final view settings - selected_week: 2025-W11, show_all: False
2025-03-12 15:18:45,082 [INFO] Found 20 time entries for week 2025-W11
2025-03-12 15:59:45,667 [ERROR] Exception on /static/js/file-upload.js [GET]
Traceback (most recent call last):
  File "/usr/lib/python3/dist-packages/flask/app.py", line 1820, in full_dispatch_request
    rv = self.dispatch_request()
         ^^^^^^^^^^^^^^^^^^^^^^^
  File "/usr/lib/python3/dist-packages/flask/app.py", line 1796, in dispatch_request
    return self.ensure_sync(self.view_functions[rule.endpoint])(**view_args)
           ^^^^^^^^^^^^^^^^^^^^^^^^^^^^^^^^^^^^^^^^^^^^^^^^^^^^^^^^^^^^^^^^^
  File "/usr/lib/python3/dist-packages/flask/app.py", line 713, in <lambda>
    view_func=lambda **kw: self_ref().send_static_file(**kw),  # type: ignore # noqa: B950
                           ^^^^^^^^^^^^^^^^^^^^^^^^^^^^^^^^^
  File "/usr/lib/python3/dist-packages/flask/scaffold.py", line 331, in send_static_file
    return send_from_directory(
           ^^^^^^^^^^^^^^^^^^^^
  File "/usr/lib/python3/dist-packages/flask/helpers.py", line 590, in send_from_directory
    return werkzeug.utils.send_from_directory(  # type: ignore[return-value]
           ^^^^^^^^^^^^^^^^^^^^^^^^^^^^^^^^^^^^^^^^^^^^^^^^^^^^^^^^^^^^^^^^^
  File "/usr/lib/python3/dist-packages/werkzeug/utils.py", line 586, in send_from_directory
    raise NotFound()
werkzeug.exceptions.NotFound: 404 Not Found: The requested URL was not found on the server. If you entered the URL manually please check your spelling and try again.

During handling of the above exception, another exception occurred:

Traceback (most recent call last):
  File "/usr/lib/python3/dist-packages/flask/app.py", line 2525, in wsgi_app
    response = self.full_dispatch_request()
               ^^^^^^^^^^^^^^^^^^^^^^^^^^^^
  File "/usr/lib/python3/dist-packages/flask/app.py", line 1822, in full_dispatch_request
    rv = self.handle_user_exception(e)
         ^^^^^^^^^^^^^^^^^^^^^^^^^^^^^
  File "/usr/lib/python3/dist-packages/flask/app.py", line 1666, in handle_user_exception
    return self.handle_http_exception(e)
           ^^^^^^^^^^^^^^^^^^^^^^^^^^^^^
  File "/usr/lib/python3/dist-packages/flask/app.py", line 1606, in handle_http_exception
    return self.ensure_sync(handler)(e)
           ^^^^^^^^^^^^^^^^^^^^^^^^^^^^
  File "/home/Jobmanager/app/__init__.py", line 93, in page_not_found
    return app.render_template('404.html'), 404
           ^^^^^^^^^^^^^^^^^^^
AttributeError: 'Flask' object has no attribute 'render_template'
2025-03-12 15:59:51,113 [ERROR] Exception on /static/js/file-upload.js [GET]
Traceback (most recent call last):
  File "/usr/lib/python3/dist-packages/flask/app.py", line 1820, in full_dispatch_request
    rv = self.dispatch_request()
         ^^^^^^^^^^^^^^^^^^^^^^^
  File "/usr/lib/python3/dist-packages/flask/app.py", line 1796, in dispatch_request
    return self.ensure_sync(self.view_functions[rule.endpoint])(**view_args)
           ^^^^^^^^^^^^^^^^^^^^^^^^^^^^^^^^^^^^^^^^^^^^^^^^^^^^^^^^^^^^^^^^^
  File "/usr/lib/python3/dist-packages/flask/app.py", line 713, in <lambda>
    view_func=lambda **kw: self_ref().send_static_file(**kw),  # type: ignore # noqa: B950
                           ^^^^^^^^^^^^^^^^^^^^^^^^^^^^^^^^^
  File "/usr/lib/python3/dist-packages/flask/scaffold.py", line 331, in send_static_file
    return send_from_directory(
           ^^^^^^^^^^^^^^^^^^^^
  File "/usr/lib/python3/dist-packages/flask/helpers.py", line 590, in send_from_directory
    return werkzeug.utils.send_from_directory(  # type: ignore[return-value]
           ^^^^^^^^^^^^^^^^^^^^^^^^^^^^^^^^^^^^^^^^^^^^^^^^^^^^^^^^^^^^^^^^^
  File "/usr/lib/python3/dist-packages/werkzeug/utils.py", line 586, in send_from_directory
    raise NotFound()
werkzeug.exceptions.NotFound: 404 Not Found: The requested URL was not found on the server. If you entered the URL manually please check your spelling and try again.

During handling of the above exception, another exception occurred:

Traceback (most recent call last):
  File "/usr/lib/python3/dist-packages/flask/app.py", line 2525, in wsgi_app
    response = self.full_dispatch_request()
               ^^^^^^^^^^^^^^^^^^^^^^^^^^^^
  File "/usr/lib/python3/dist-packages/flask/app.py", line 1822, in full_dispatch_request
    rv = self.handle_user_exception(e)
         ^^^^^^^^^^^^^^^^^^^^^^^^^^^^^
  File "/usr/lib/python3/dist-packages/flask/app.py", line 1666, in handle_user_exception
    return self.handle_http_exception(e)
           ^^^^^^^^^^^^^^^^^^^^^^^^^^^^^
  File "/usr/lib/python3/dist-packages/flask/app.py", line 1606, in handle_http_exception
    return self.ensure_sync(handler)(e)
           ^^^^^^^^^^^^^^^^^^^^^^^^^^^^
  File "/home/Jobmanager/app/__init__.py", line 93, in page_not_found
    return app.render_template('404.html'), 404
           ^^^^^^^^^^^^^^^^^^^
AttributeError: 'Flask' object has no attribute 'render_template'
2025-03-12 15:59:58,906 [INFO] Stopping timer for job 48
2025-03-12 16:00:08,665 [ERROR] Exception on /static/js/file-upload.js [GET]
Traceback (most recent call last):
  File "/usr/lib/python3/dist-packages/flask/app.py", line 1820, in full_dispatch_request
    rv = self.dispatch_request()
         ^^^^^^^^^^^^^^^^^^^^^^^
  File "/usr/lib/python3/dist-packages/flask/app.py", line 1796, in dispatch_request
    return self.ensure_sync(self.view_functions[rule.endpoint])(**view_args)
           ^^^^^^^^^^^^^^^^^^^^^^^^^^^^^^^^^^^^^^^^^^^^^^^^^^^^^^^^^^^^^^^^^
  File "/usr/lib/python3/dist-packages/flask/app.py", line 713, in <lambda>
    view_func=lambda **kw: self_ref().send_static_file(**kw),  # type: ignore # noqa: B950
                           ^^^^^^^^^^^^^^^^^^^^^^^^^^^^^^^^^
  File "/usr/lib/python3/dist-packages/flask/scaffold.py", line 331, in send_static_file
    return send_from_directory(
           ^^^^^^^^^^^^^^^^^^^^
  File "/usr/lib/python3/dist-packages/flask/helpers.py", line 590, in send_from_directory
    return werkzeug.utils.send_from_directory(  # type: ignore[return-value]
           ^^^^^^^^^^^^^^^^^^^^^^^^^^^^^^^^^^^^^^^^^^^^^^^^^^^^^^^^^^^^^^^^^
  File "/usr/lib/python3/dist-packages/werkzeug/utils.py", line 586, in send_from_directory
    raise NotFound()
werkzeug.exceptions.NotFound: 404 Not Found: The requested URL was not found on the server. If you entered the URL manually please check your spelling and try again.

During handling of the above exception, another exception occurred:

Traceback (most recent call last):
  File "/usr/lib/python3/dist-packages/flask/app.py", line 2525, in wsgi_app
    response = self.full_dispatch_request()
               ^^^^^^^^^^^^^^^^^^^^^^^^^^^^
  File "/usr/lib/python3/dist-packages/flask/app.py", line 1822, in full_dispatch_request
    rv = self.handle_user_exception(e)
         ^^^^^^^^^^^^^^^^^^^^^^^^^^^^^
  File "/usr/lib/python3/dist-packages/flask/app.py", line 1666, in handle_user_exception
    return self.handle_http_exception(e)
           ^^^^^^^^^^^^^^^^^^^^^^^^^^^^^
  File "/usr/lib/python3/dist-packages/flask/app.py", line 1606, in handle_http_exception
    return self.ensure_sync(handler)(e)
           ^^^^^^^^^^^^^^^^^^^^^^^^^^^^
  File "/home/Jobmanager/app/__init__.py", line 93, in page_not_found
    return app.render_template('404.html'), 404
           ^^^^^^^^^^^^^^^^^^^
AttributeError: 'Flask' object has no attribute 'render_template'
2025-03-12 16:00:53,577 [ERROR] Exception on /static/js/file-upload.js [GET]
Traceback (most recent call last):
  File "/usr/lib/python3/dist-packages/flask/app.py", line 1820, in full_dispatch_request
    rv = self.dispatch_request()
         ^^^^^^^^^^^^^^^^^^^^^^^
  File "/usr/lib/python3/dist-packages/flask/app.py", line 1796, in dispatch_request
    return self.ensure_sync(self.view_functions[rule.endpoint])(**view_args)
           ^^^^^^^^^^^^^^^^^^^^^^^^^^^^^^^^^^^^^^^^^^^^^^^^^^^^^^^^^^^^^^^^^
  File "/usr/lib/python3/dist-packages/flask/app.py", line 713, in <lambda>
    view_func=lambda **kw: self_ref().send_static_file(**kw),  # type: ignore # noqa: B950
                           ^^^^^^^^^^^^^^^^^^^^^^^^^^^^^^^^^
  File "/usr/lib/python3/dist-packages/flask/scaffold.py", line 331, in send_static_file
    return send_from_directory(
           ^^^^^^^^^^^^^^^^^^^^
  File "/usr/lib/python3/dist-packages/flask/helpers.py", line 590, in send_from_directory
    return werkzeug.utils.send_from_directory(  # type: ignore[return-value]
           ^^^^^^^^^^^^^^^^^^^^^^^^^^^^^^^^^^^^^^^^^^^^^^^^^^^^^^^^^^^^^^^^^
  File "/usr/lib/python3/dist-packages/werkzeug/utils.py", line 586, in send_from_directory
    raise NotFound()
werkzeug.exceptions.NotFound: 404 Not Found: The requested URL was not found on the server. If you entered the URL manually please check your spelling and try again.

During handling of the above exception, another exception occurred:

Traceback (most recent call last):
  File "/usr/lib/python3/dist-packages/flask/app.py", line 2525, in wsgi_app
    response = self.full_dispatch_request()
               ^^^^^^^^^^^^^^^^^^^^^^^^^^^^
  File "/usr/lib/python3/dist-packages/flask/app.py", line 1822, in full_dispatch_request
    rv = self.handle_user_exception(e)
         ^^^^^^^^^^^^^^^^^^^^^^^^^^^^^
  File "/usr/lib/python3/dist-packages/flask/app.py", line 1666, in handle_user_exception
    return self.handle_http_exception(e)
           ^^^^^^^^^^^^^^^^^^^^^^^^^^^^^
  File "/usr/lib/python3/dist-packages/flask/app.py", line 1606, in handle_http_exception
    return self.ensure_sync(handler)(e)
           ^^^^^^^^^^^^^^^^^^^^^^^^^^^^
  File "/home/Jobmanager/app/__init__.py", line 93, in page_not_found
    return app.render_template('404.html'), 404
           ^^^^^^^^^^^^^^^^^^^
AttributeError: 'Flask' object has no attribute 'render_template'
2025-03-12 16:01:08,789 [ERROR] Exception on /static/js/file-upload.js [GET]
Traceback (most recent call last):
  File "/usr/lib/python3/dist-packages/flask/app.py", line 1820, in full_dispatch_request
    rv = self.dispatch_request()
         ^^^^^^^^^^^^^^^^^^^^^^^
  File "/usr/lib/python3/dist-packages/flask/app.py", line 1796, in dispatch_request
    return self.ensure_sync(self.view_functions[rule.endpoint])(**view_args)
           ^^^^^^^^^^^^^^^^^^^^^^^^^^^^^^^^^^^^^^^^^^^^^^^^^^^^^^^^^^^^^^^^^
  File "/usr/lib/python3/dist-packages/flask/app.py", line 713, in <lambda>
    view_func=lambda **kw: self_ref().send_static_file(**kw),  # type: ignore # noqa: B950
                           ^^^^^^^^^^^^^^^^^^^^^^^^^^^^^^^^^
  File "/usr/lib/python3/dist-packages/flask/scaffold.py", line 331, in send_static_file
    return send_from_directory(
           ^^^^^^^^^^^^^^^^^^^^
  File "/usr/lib/python3/dist-packages/flask/helpers.py", line 590, in send_from_directory
    return werkzeug.utils.send_from_directory(  # type: ignore[return-value]
           ^^^^^^^^^^^^^^^^^^^^^^^^^^^^^^^^^^^^^^^^^^^^^^^^^^^^^^^^^^^^^^^^^
  File "/usr/lib/python3/dist-packages/werkzeug/utils.py", line 586, in send_from_directory
    raise NotFound()
werkzeug.exceptions.NotFound: 404 Not Found: The requested URL was not found on the server. If you entered the URL manually please check your spelling and try again.

During handling of the above exception, another exception occurred:

Traceback (most recent call last):
  File "/usr/lib/python3/dist-packages/flask/app.py", line 2525, in wsgi_app
    response = self.full_dispatch_request()
               ^^^^^^^^^^^^^^^^^^^^^^^^^^^^
  File "/usr/lib/python3/dist-packages/flask/app.py", line 1822, in full_dispatch_request
    rv = self.handle_user_exception(e)
         ^^^^^^^^^^^^^^^^^^^^^^^^^^^^^
  File "/usr/lib/python3/dist-packages/flask/app.py", line 1666, in handle_user_exception
    return self.handle_http_exception(e)
           ^^^^^^^^^^^^^^^^^^^^^^^^^^^^^
  File "/usr/lib/python3/dist-packages/flask/app.py", line 1606, in handle_http_exception
    return self.ensure_sync(handler)(e)
           ^^^^^^^^^^^^^^^^^^^^^^^^^^^^
  File "/home/Jobmanager/app/__init__.py", line 93, in page_not_found
    return app.render_template('404.html'), 404
           ^^^^^^^^^^^^^^^^^^^
AttributeError: 'Flask' object has no attribute 'render_template'
2025-03-12 16:01:08,805 [ERROR] Exception on /favicon.ico [GET]
Traceback (most recent call last):
  File "/usr/lib/python3/dist-packages/flask/app.py", line 1820, in full_dispatch_request
    rv = self.dispatch_request()
         ^^^^^^^^^^^^^^^^^^^^^^^
  File "/usr/lib/python3/dist-packages/flask/app.py", line 1785, in dispatch_request
    self.raise_routing_exception(req)
  File "/usr/lib/python3/dist-packages/flask/app.py", line 1767, in raise_routing_exception
    raise request.routing_exception  # type: ignore
    ^^^^^^^^^^^^^^^^^^^^^^^^^^^^^^^
  File "/usr/lib/python3/dist-packages/flask/ctx.py", line 351, in match_request
    result = self.url_adapter.match(return_rule=True)  # type: ignore
             ^^^^^^^^^^^^^^^^^^^^^^^^^^^^^^^^^^^^^^^^
  File "/usr/lib/python3/dist-packages/werkzeug/routing/map.py", line 624, in match
    raise NotFound() from None
werkzeug.exceptions.NotFound: 404 Not Found: The requested URL was not found on the server. If you entered the URL manually please check your spelling and try again.

During handling of the above exception, another exception occurred:

Traceback (most recent call last):
  File "/usr/lib/python3/dist-packages/flask/app.py", line 2525, in wsgi_app
    response = self.full_dispatch_request()
               ^^^^^^^^^^^^^^^^^^^^^^^^^^^^
  File "/usr/lib/python3/dist-packages/flask/app.py", line 1822, in full_dispatch_request
    rv = self.handle_user_exception(e)
         ^^^^^^^^^^^^^^^^^^^^^^^^^^^^^
  File "/usr/lib/python3/dist-packages/flask/app.py", line 1666, in handle_user_exception
    return self.handle_http_exception(e)
           ^^^^^^^^^^^^^^^^^^^^^^^^^^^^^
  File "/usr/lib/python3/dist-packages/flask/app.py", line 1606, in handle_http_exception
    return self.ensure_sync(handler)(e)
           ^^^^^^^^^^^^^^^^^^^^^^^^^^^^
  File "/home/Jobmanager/app/__init__.py", line 93, in page_not_found
    return app.render_template('404.html'), 404
           ^^^^^^^^^^^^^^^^^^^
AttributeError: 'Flask' object has no attribute 'render_template'
2025-03-12 16:01:41,707 [INFO] Weekly summary request - selected_week: None, show_all: False
2025-03-12 16:01:41,707 [INFO] No week selected, using current week: 2025-W11
2025-03-12 16:01:41,707 [INFO] Fetching available weeks
2025-03-12 16:01:41,707 [INFO] Found 36 distinct dates with time entries
2025-03-12 16:01:41,708 [INFO] Processed 6 unique weeks
2025-03-12 16:01:41,708 [INFO] Final view settings - selected_week: 2025-W11, show_all: False
2025-03-12 16:01:41,708 [INFO] Found 20 time entries for week 2025-W11
2025-03-12 16:01:41,742 [ERROR] Exception on /favicon.ico [GET]
Traceback (most recent call last):
  File "/usr/lib/python3/dist-packages/flask/app.py", line 1820, in full_dispatch_request
    rv = self.dispatch_request()
         ^^^^^^^^^^^^^^^^^^^^^^^
  File "/usr/lib/python3/dist-packages/flask/app.py", line 1785, in dispatch_request
    self.raise_routing_exception(req)
  File "/usr/lib/python3/dist-packages/flask/app.py", line 1767, in raise_routing_exception
    raise request.routing_exception  # type: ignore
    ^^^^^^^^^^^^^^^^^^^^^^^^^^^^^^^
  File "/usr/lib/python3/dist-packages/flask/ctx.py", line 351, in match_request
    result = self.url_adapter.match(return_rule=True)  # type: ignore
             ^^^^^^^^^^^^^^^^^^^^^^^^^^^^^^^^^^^^^^^^
  File "/usr/lib/python3/dist-packages/werkzeug/routing/map.py", line 624, in match
    raise NotFound() from None
werkzeug.exceptions.NotFound: 404 Not Found: The requested URL was not found on the server. If you entered the URL manually please check your spelling and try again.

During handling of the above exception, another exception occurred:

Traceback (most recent call last):
  File "/usr/lib/python3/dist-packages/flask/app.py", line 2525, in wsgi_app
    response = self.full_dispatch_request()
               ^^^^^^^^^^^^^^^^^^^^^^^^^^^^
  File "/usr/lib/python3/dist-packages/flask/app.py", line 1822, in full_dispatch_request
    rv = self.handle_user_exception(e)
         ^^^^^^^^^^^^^^^^^^^^^^^^^^^^^
  File "/usr/lib/python3/dist-packages/flask/app.py", line 1666, in handle_user_exception
    return self.handle_http_exception(e)
           ^^^^^^^^^^^^^^^^^^^^^^^^^^^^^
  File "/usr/lib/python3/dist-packages/flask/app.py", line 1606, in handle_http_exception
    return self.ensure_sync(handler)(e)
           ^^^^^^^^^^^^^^^^^^^^^^^^^^^^
  File "/home/Jobmanager/app/__init__.py", line 93, in page_not_found
    return app.render_template('404.html'), 404
           ^^^^^^^^^^^^^^^^^^^
AttributeError: 'Flask' object has no attribute 'render_template'
